[2024-12-08T13:57:48.504+0000] {local_task_job_runner.py:123} INFO - ::group::Pre task execution logs
[2024-12-08T13:57:48.745+0000] {taskinstance.py:2613} INFO - Dependencies all met for dep_context=non-requeueable deps ti=<TaskInstance: parallel_historical_price_with_group.process_groups.process_group_0 manual__2024-12-08T13:57:28.291909+00:00 [queued]>
[2024-12-08T13:57:49.126+0000] {taskinstance.py:2613} INFO - Dependencies all met for dep_context=requeueable deps ti=<TaskInstance: parallel_historical_price_with_group.process_groups.process_group_0 manual__2024-12-08T13:57:28.291909+00:00 [queued]>
[2024-12-08T13:57:49.127+0000] {taskinstance.py:2866} INFO - Starting attempt 1 of 1
[2024-12-08T13:57:49.389+0000] {taskinstance.py:2889} INFO - Executing <Task(PythonOperator): process_groups.process_group_0> on 2024-12-08 13:57:28.291909+00:00
[2024-12-08T13:57:49.584+0000] {logging_mixin.py:190} WARNING - /usr/local/lib/python3.12/site-packages/airflow/task/task_runner/standard_task_runner.py:70 DeprecationWarning: This process (pid=3142) is multi-threaded, use of fork() may lead to deadlocks in the child.
[2024-12-08T13:57:49.597+0000] {standard_task_runner.py:72} INFO - Started process 3180 to run task
[2024-12-08T13:57:49.614+0000] {standard_task_runner.py:104} INFO - Running: ['airflow', 'tasks', 'run', 'parallel_historical_price_with_group', 'process_groups.process_group_0', 'manual__2024-12-08T13:57:28.291909+00:00', '--job-id', '142', '--raw', '--subdir', 'DAGS_FOLDER/Extract_history_price_data.py', '--cfg-path', '/tmp/tmpglssopwz']
[2024-12-08T13:57:49.668+0000] {standard_task_runner.py:105} INFO - Job 142: Subtask process_groups.process_group_0
[2024-12-08T13:57:50.808+0000] {task_command.py:467} INFO - Running <TaskInstance: parallel_historical_price_with_group.process_groups.process_group_0 manual__2024-12-08T13:57:28.291909+00:00 [running]> on host 80c3b7e46742
[2024-12-08T13:57:58.670+0000] {job.py:229} INFO - Heartbeat recovered after 10.94 seconds
[2024-12-08T13:58:02.731+0000] {taskinstance.py:3132} INFO - Exporting env vars: AIRFLOW_CTX_DAG_OWNER='airflowDWH' AIRFLOW_CTX_DAG_ID='parallel_historical_price_with_group' AIRFLOW_CTX_TASK_ID='process_groups.process_group_0' AIRFLOW_CTX_EXECUTION_DATE='2024-12-08T13:57:28.291909+00:00' AIRFLOW_CTX_TRY_NUMBER='1' AIRFLOW_CTX_DAG_RUN_ID='manual__2024-12-08T13:57:28.291909+00:00'
[2024-12-08T13:58:02.736+0000] {taskinstance.py:731} INFO - ::endgroup::
[2024-12-08T13:58:05.962+0000] {data_explorer.py:64} WARNING - Thông tin niêm yết & giao dịch sẽ được truy xuất từ TCBS
[2024-12-08T13:58:10.263+0000] {data_explorer.py:64} WARNING - Thông tin niêm yết & giao dịch sẽ được truy xuất từ TCBS
[2024-12-08T13:58:12.937+0000] {data_explorer.py:64} WARNING - Thông tin niêm yết & giao dịch sẽ được truy xuất từ TCBS
[2024-12-08T13:58:29.401+0000] {data_explorer.py:64} WARNING - Thông tin niêm yết & giao dịch sẽ được truy xuất từ TCBS
[2024-12-08T13:58:30.791+0000] {job.py:229} INFO - Heartbeat recovered after 19.69 seconds
[2024-12-08T13:58:33.871+0000] {data_explorer.py:64} WARNING - Thông tin niêm yết & giao dịch sẽ được truy xuất từ TCBS
[2024-12-08T13:58:38.903+0000] {data_explorer.py:64} WARNING - Thông tin niêm yết & giao dịch sẽ được truy xuất từ TCBS
[2024-12-08T13:58:42.968+0000] {data_explorer.py:64} WARNING - Thông tin niêm yết & giao dịch sẽ được truy xuất từ TCBS
[2024-12-08T13:58:47.239+0000] {data_explorer.py:64} WARNING - Thông tin niêm yết & giao dịch sẽ được truy xuất từ TCBS
[2024-12-08T13:59:03.161+0000] {taskinstance.py:3311} ERROR - Task failed with exception
Traceback (most recent call last):
  File "/usr/local/lib/python3.12/site-packages/urllib3/connection.py", line 199, in _new_conn
    sock = connection.create_connection(
           ^^^^^^^^^^^^^^^^^^^^^^^^^^^^^
  File "/usr/local/lib/python3.12/site-packages/urllib3/util/connection.py", line 60, in create_connection
    for res in socket.getaddrinfo(host, port, family, socket.SOCK_STREAM):
               ^^^^^^^^^^^^^^^^^^^^^^^^^^^^^^^^^^^^^^^^^^^^^^^^^^^^^^^^^^
  File "/usr/local/lib/python3.12/socket.py", line 976, in getaddrinfo
    for res in _socket.getaddrinfo(host, port, family, type, proto, flags):
               ^^^^^^^^^^^^^^^^^^^^^^^^^^^^^^^^^^^^^^^^^^^^^^^^^^^^^^^^^^^
socket.gaierror: [Errno -3] Temporary failure in name resolution

The above exception was the direct cause of the following exception:

Traceback (most recent call last):
  File "/usr/local/lib/python3.12/site-packages/urllib3/connectionpool.py", line 789, in urlopen
    response = self._make_request(
               ^^^^^^^^^^^^^^^^^^^
  File "/usr/local/lib/python3.12/site-packages/urllib3/connectionpool.py", line 490, in _make_request
    raise new_e
  File "/usr/local/lib/python3.12/site-packages/urllib3/connectionpool.py", line 466, in _make_request
    self._validate_conn(conn)
  File "/usr/local/lib/python3.12/site-packages/urllib3/connectionpool.py", line 1095, in _validate_conn
    conn.connect()
  File "/usr/local/lib/python3.12/site-packages/urllib3/connection.py", line 693, in connect
    self.sock = sock = self._new_conn()
                       ^^^^^^^^^^^^^^^^
  File "/usr/local/lib/python3.12/site-packages/urllib3/connection.py", line 206, in _new_conn
    raise NameResolutionError(self.host, self, e) from e
urllib3.exceptions.NameResolutionError: <urllib3.connection.HTTPSConnection object at 0x7f18bec7aff0>: Failed to resolve 'trading.vietcap.com.vn' ([Errno -3] Temporary failure in name resolution)

The above exception was the direct cause of the following exception:

Traceback (most recent call last):
  File "/usr/local/lib/python3.12/site-packages/requests/adapters.py", line 667, in send
    resp = conn.urlopen(
           ^^^^^^^^^^^^^
  File "/usr/local/lib/python3.12/site-packages/urllib3/connectionpool.py", line 843, in urlopen
    retries = retries.increment(
              ^^^^^^^^^^^^^^^^^^
  File "/usr/local/lib/python3.12/site-packages/urllib3/util/retry.py", line 519, in increment
    raise MaxRetryError(_pool, url, reason) from reason  # type: ignore[arg-type]
    ^^^^^^^^^^^^^^^^^^^^^^^^^^^^^^^^^^^^^^^^^^^^^^^^^^^
urllib3.exceptions.MaxRetryError: HTTPSConnectionPool(host='trading.vietcap.com.vn', port=443): Max retries exceeded with url: /api/chart/OHLCChart/gap (Caused by NameResolutionError("<urllib3.connection.HTTPSConnection object at 0x7f18bec7aff0>: Failed to resolve 'trading.vietcap.com.vn' ([Errno -3] Temporary failure in name resolution)"))

During handling of the above exception, another exception occurred:

Traceback (most recent call last):
  File "/usr/local/lib/python3.12/site-packages/airflow/models/taskinstance.py", line 767, in _execute_task
    result = _execute_callable(context=context, **execute_callable_kwargs)
             ^^^^^^^^^^^^^^^^^^^^^^^^^^^^^^^^^^^^^^^^^^^^^^^^^^^^^^^^^^^^^
  File "/usr/local/lib/python3.12/site-packages/airflow/models/taskinstance.py", line 733, in _execute_callable
    return ExecutionCallableRunner(
           ^^^^^^^^^^^^^^^^^^^^^^^^
  File "/usr/local/lib/python3.12/site-packages/airflow/utils/operator_helpers.py", line 252, in run
    return self.func(*args, **kwargs)
           ^^^^^^^^^^^^^^^^^^^^^^^^^^
  File "/usr/local/lib/python3.12/site-packages/airflow/models/baseoperator.py", line 417, in wrapper
    return func(self, *args, **kwargs)
           ^^^^^^^^^^^^^^^^^^^^^^^^^^^
  File "/usr/local/lib/python3.12/site-packages/airflow/operators/python.py", line 238, in execute
    return_value = self.execute_callable()
                   ^^^^^^^^^^^^^^^^^^^^^^^
  File "/usr/local/lib/python3.12/site-packages/airflow/operators/python.py", line 256, in execute_callable
    return runner.run(*self.op_args, **self.op_kwargs)
           ^^^^^^^^^^^^^^^^^^^^^^^^^^^^^^^^^^^^^^^^^^^
  File "/usr/local/lib/python3.12/site-packages/airflow/utils/operator_helpers.py", line 252, in run
    return self.func(*args, **kwargs)
           ^^^^^^^^^^^^^^^^^^^^^^^^^^
  File "/opt/airflow/dags/Extract_history_price_data.py", line 27, in process_group
    result = historical_price(stock_codes)
             ^^^^^^^^^^^^^^^^^^^^^^^^^^^^^
  File "/opt/Tasks/HistoricalData/Historical_price_stock.py", line 12, in historical_price
    HisPriceDF = stock.quote.history(start='2015-01-01', end='2024-12-7')
                 ^^^^^^^^^^^^^^^^^^^^^^^^^^^^^^^^^^^^^^^^^^^^^^^^^^^^^^^^
  File "/usr/local/lib/python3.12/site-packages/vnstock3/common/data/data_explorer.py", line 127, in history
    return self.data_source.history(**kwargs)
           ^^^^^^^^^^^^^^^^^^^^^^^^^^^^^^^^^^
  File "/usr/local/lib/python3.12/site-packages/vnstock3/explorer/vci/quote.py", line 111, in history
    response = requests.post(url, headers=self.headers, data=payload)
               ^^^^^^^^^^^^^^^^^^^^^^^^^^^^^^^^^^^^^^^^^^^^^^^^^^^^^^
  File "/usr/local/lib/python3.12/site-packages/requests/api.py", line 115, in post
    return request("post", url, data=data, json=json, **kwargs)
           ^^^^^^^^^^^^^^^^^^^^^^^^^^^^^^^^^^^^^^^^^^^^^^^^^^^^
  File "/usr/local/lib/python3.12/site-packages/requests/api.py", line 59, in request
    return session.request(method=method, url=url, **kwargs)
           ^^^^^^^^^^^^^^^^^^^^^^^^^^^^^^^^^^^^^^^^^^^^^^^^^
  File "/usr/local/lib/python3.12/site-packages/requests/sessions.py", line 589, in request
    resp = self.send(prep, **send_kwargs)
           ^^^^^^^^^^^^^^^^^^^^^^^^^^^^^^
  File "/usr/local/lib/python3.12/site-packages/requests/sessions.py", line 703, in send
    r = adapter.send(request, **kwargs)
        ^^^^^^^^^^^^^^^^^^^^^^^^^^^^^^^
  File "/usr/local/lib/python3.12/site-packages/requests/adapters.py", line 700, in send
    raise ConnectionError(e, request=request)
requests.exceptions.ConnectionError: HTTPSConnectionPool(host='trading.vietcap.com.vn', port=443): Max retries exceeded with url: /api/chart/OHLCChart/gap (Caused by NameResolutionError("<urllib3.connection.HTTPSConnection object at 0x7f18bec7aff0>: Failed to resolve 'trading.vietcap.com.vn' ([Errno -3] Temporary failure in name resolution)"))
[2024-12-08T13:59:08.341+0000] {job.py:229} INFO - Heartbeat recovered after 24.35 seconds
[2024-12-08T13:59:13.235+0000] {taskinstance.py:1225} INFO - Marking task as FAILED. dag_id=parallel_historical_price_with_group, task_id=process_groups.process_group_0, run_id=manual__2024-12-08T13:57:28.291909+00:00, execution_date=20241208T135728, start_date=20241208T135748, end_date=20241208T135912
[2024-12-08T13:59:17.534+0000] {local_task_job_runner.py:346} WARNING - State of this instance has been externally set to success. Terminating instance.
[2024-12-08T13:59:18.122+0000] {local_task_job_runner.py:245} INFO - ::endgroup::
[2024-12-08T13:59:18.668+0000] {process_utils.py:132} INFO - Sending 15 to group 3180. PIDs of all processes in the group: [3180]
[2024-12-08T13:59:18.695+0000] {process_utils.py:87} INFO - Sending the signal 15 to group 3180
[2024-12-08T13:59:18.765+0000] {taskinstance.py:3093} ERROR - Received SIGTERM. Terminating subprocesses.
[2024-12-08T13:59:19.175+0000] {taskinstance.py:340} INFO - ::group::Post task execution logs
[2024-12-08T13:59:20.142+0000] {process_utils.py:80} INFO - Process psutil.Process(pid=3180, status='terminated', exitcode=2, started='13:57:49') (3180) terminated with exit code 2
