[2024-12-14T03:38:45.817+0000] {local_task_job_runner.py:123} INFO - ::group::Pre task execution logs
[2024-12-14T03:38:45.880+0000] {taskinstance.py:2613} INFO - Dependencies all met for dep_context=non-requeueable deps ti=<TaskInstance: parallel_new_financial_reports.Load_to_fact_financials manual__2024-12-14T03:38:40.881735+00:00 [queued]>
[2024-12-14T03:38:45.906+0000] {taskinstance.py:2613} INFO - Dependencies all met for dep_context=requeueable deps ti=<TaskInstance: parallel_new_financial_reports.Load_to_fact_financials manual__2024-12-14T03:38:40.881735+00:00 [queued]>
[2024-12-14T03:38:45.906+0000] {taskinstance.py:2866} INFO - Starting attempt 1 of 1
[2024-12-14T03:38:45.944+0000] {taskinstance.py:2889} INFO - Executing <Task(PythonOperator): Load_to_fact_financials> on 2024-12-14 03:38:40.881735+00:00
[2024-12-14T03:38:45.959+0000] {logging_mixin.py:190} WARNING - /usr/local/lib/python3.12/site-packages/airflow/task/task_runner/standard_task_runner.py:70 DeprecationWarning: This process (pid=5800) is multi-threaded, use of fork() may lead to deadlocks in the child.
[2024-12-14T03:38:45.960+0000] {standard_task_runner.py:72} INFO - Started process 5802 to run task
[2024-12-14T03:38:45.958+0000] {standard_task_runner.py:104} INFO - Running: ['airflow', 'tasks', 'run', 'parallel_new_financial_reports', 'Load_to_fact_financials', 'manual__2024-12-14T03:38:40.881735+00:00', '--job-id', '399', '--raw', '--subdir', 'DAGS_FOLDER/Extract_new_financial_data.py', '--cfg-path', '/tmp/tmplbz67csv']
[2024-12-14T03:38:45.961+0000] {standard_task_runner.py:105} INFO - Job 399: Subtask Load_to_fact_financials
[2024-12-14T03:38:46.203+0000] {task_command.py:467} INFO - Running <TaskInstance: parallel_new_financial_reports.Load_to_fact_financials manual__2024-12-14T03:38:40.881735+00:00 [running]> on host 2f7cc6f48508
[2024-12-14T03:38:46.644+0000] {taskinstance.py:3132} INFO - Exporting env vars: AIRFLOW_CTX_DAG_OWNER='airflowDWH' AIRFLOW_CTX_DAG_ID='parallel_new_financial_reports' AIRFLOW_CTX_TASK_ID='Load_to_fact_financials' AIRFLOW_CTX_EXECUTION_DATE='2024-12-14T03:38:40.881735+00:00' AIRFLOW_CTX_TRY_NUMBER='1' AIRFLOW_CTX_DAG_RUN_ID='manual__2024-12-14T03:38:40.881735+00:00'
[2024-12-14T03:38:46.646+0000] {taskinstance.py:731} INFO - ::endgroup::
[2024-12-14T03:38:46.713+0000] {base.py:84} INFO - Retrieving connection 'load_to_staging'
[2024-12-14T03:38:47.353+0000] {base.py:84} INFO - Retrieving connection 'load_to_dwh'
[2024-12-14T03:39:00.365+0000] {taskinstance.py:3311} ERROR - Task failed with exception
Traceback (most recent call last):
  File "/usr/local/lib/python3.12/site-packages/airflow/models/taskinstance.py", line 767, in _execute_task
    result = _execute_callable(context=context, **execute_callable_kwargs)
             ^^^^^^^^^^^^^^^^^^^^^^^^^^^^^^^^^^^^^^^^^^^^^^^^^^^^^^^^^^^^^
  File "/usr/local/lib/python3.12/site-packages/airflow/models/taskinstance.py", line 733, in _execute_callable
    return ExecutionCallableRunner(
           ^^^^^^^^^^^^^^^^^^^^^^^^
  File "/usr/local/lib/python3.12/site-packages/airflow/utils/operator_helpers.py", line 252, in run
    return self.func(*args, **kwargs)
           ^^^^^^^^^^^^^^^^^^^^^^^^^^
  File "/usr/local/lib/python3.12/site-packages/airflow/models/baseoperator.py", line 417, in wrapper
    return func(self, *args, **kwargs)
           ^^^^^^^^^^^^^^^^^^^^^^^^^^^
  File "/usr/local/lib/python3.12/site-packages/airflow/operators/python.py", line 238, in execute
    return_value = self.execute_callable()
                   ^^^^^^^^^^^^^^^^^^^^^^^
  File "/usr/local/lib/python3.12/site-packages/airflow/operators/python.py", line 256, in execute_callable
    return runner.run(*self.op_args, **self.op_kwargs)
           ^^^^^^^^^^^^^^^^^^^^^^^^^^^^^^^^^^^^^^^^^^^
  File "/usr/local/lib/python3.12/site-packages/airflow/utils/operator_helpers.py", line 252, in run
    return self.func(*args, **kwargs)
           ^^^^^^^^^^^^^^^^^^^^^^^^^^
  File "/opt/Tasks/transform_and_load_data/transform_and_load.py", line 213, in fact_financials_tranform_load
    dwh_cursor.executemany(sql_insert, transformed_data)
psycopg2.errors.ForeignKeyViolation: insert or update on table "fact_fanancials" violates foreign key constraint "fact_fanancials_time_period_id_fkey"
DETAIL:  Key (time_period_id)=(Q1 2011) is not present in table "dim_time_period".

[2024-12-14T03:39:00.407+0000] {taskinstance.py:1225} INFO - Marking task as FAILED. dag_id=parallel_new_financial_reports, task_id=Load_to_fact_financials, run_id=manual__2024-12-14T03:38:40.881735+00:00, execution_date=20241214T033840, start_date=20241214T033845, end_date=20241214T033900
[2024-12-14T03:39:00.512+0000] {taskinstance.py:340} INFO - ::group::Post task execution logs
[2024-12-14T03:39:00.513+0000] {standard_task_runner.py:124} ERROR - Failed to execute job 399 for task Load_to_fact_financials (insert or update on table "fact_fanancials" violates foreign key constraint "fact_fanancials_time_period_id_fkey"
DETAIL:  Key (time_period_id)=(Q1 2011) is not present in table "dim_time_period".
; 5802)
Traceback (most recent call last):
  File "/usr/local/lib/python3.12/site-packages/airflow/task/task_runner/standard_task_runner.py", line 117, in _start_by_fork
    ret = args.func(args, dag=self.dag)
          ^^^^^^^^^^^^^^^^^^^^^^^^^^^^^
  File "/usr/local/lib/python3.12/site-packages/airflow/cli/cli_config.py", line 49, in command
    return func(*args, **kwargs)
           ^^^^^^^^^^^^^^^^^^^^^
  File "/usr/local/lib/python3.12/site-packages/airflow/utils/cli.py", line 116, in wrapper
    return f(*args, **kwargs)
           ^^^^^^^^^^^^^^^^^^
  File "/usr/local/lib/python3.12/site-packages/airflow/cli/commands/task_command.py", line 483, in task_run
    task_return_code = _run_task_by_selected_method(args, _dag, ti)
                       ^^^^^^^^^^^^^^^^^^^^^^^^^^^^^^^^^^^^^^^^^^^^
  File "/usr/local/lib/python3.12/site-packages/airflow/cli/commands/task_command.py", line 256, in _run_task_by_selected_method
    return _run_raw_task(args, ti)
           ^^^^^^^^^^^^^^^^^^^^^^^
  File "/usr/local/lib/python3.12/site-packages/airflow/cli/commands/task_command.py", line 341, in _run_raw_task
    return ti._run_raw_task(
           ^^^^^^^^^^^^^^^^^
  File "/usr/local/lib/python3.12/site-packages/airflow/utils/session.py", line 97, in wrapper
    return func(*args, session=session, **kwargs)
           ^^^^^^^^^^^^^^^^^^^^^^^^^^^^^^^^^^^^^^
  File "/usr/local/lib/python3.12/site-packages/airflow/models/taskinstance.py", line 3005, in _run_raw_task
    return _run_raw_task(
           ^^^^^^^^^^^^^^
  File "/usr/local/lib/python3.12/site-packages/airflow/models/taskinstance.py", line 273, in _run_raw_task
    TaskInstance._execute_task_with_callbacks(
  File "/usr/local/lib/python3.12/site-packages/airflow/models/taskinstance.py", line 3159, in _execute_task_with_callbacks
    result = self._execute_task(context, task_orig)
             ^^^^^^^^^^^^^^^^^^^^^^^^^^^^^^^^^^^^^^
  File "/usr/local/lib/python3.12/site-packages/airflow/models/taskinstance.py", line 3183, in _execute_task
    return _execute_task(self, context, task_orig)
           ^^^^^^^^^^^^^^^^^^^^^^^^^^^^^^^^^^^^^^^
  File "/usr/local/lib/python3.12/site-packages/airflow/models/taskinstance.py", line 767, in _execute_task
    result = _execute_callable(context=context, **execute_callable_kwargs)
             ^^^^^^^^^^^^^^^^^^^^^^^^^^^^^^^^^^^^^^^^^^^^^^^^^^^^^^^^^^^^^
  File "/usr/local/lib/python3.12/site-packages/airflow/models/taskinstance.py", line 733, in _execute_callable
    return ExecutionCallableRunner(
           ^^^^^^^^^^^^^^^^^^^^^^^^
  File "/usr/local/lib/python3.12/site-packages/airflow/utils/operator_helpers.py", line 252, in run
    return self.func(*args, **kwargs)
           ^^^^^^^^^^^^^^^^^^^^^^^^^^
  File "/usr/local/lib/python3.12/site-packages/airflow/models/baseoperator.py", line 417, in wrapper
    return func(self, *args, **kwargs)
           ^^^^^^^^^^^^^^^^^^^^^^^^^^^
  File "/usr/local/lib/python3.12/site-packages/airflow/operators/python.py", line 238, in execute
    return_value = self.execute_callable()
                   ^^^^^^^^^^^^^^^^^^^^^^^
  File "/usr/local/lib/python3.12/site-packages/airflow/operators/python.py", line 256, in execute_callable
    return runner.run(*self.op_args, **self.op_kwargs)
           ^^^^^^^^^^^^^^^^^^^^^^^^^^^^^^^^^^^^^^^^^^^
  File "/usr/local/lib/python3.12/site-packages/airflow/utils/operator_helpers.py", line 252, in run
    return self.func(*args, **kwargs)
           ^^^^^^^^^^^^^^^^^^^^^^^^^^
  File "/opt/Tasks/transform_and_load_data/transform_and_load.py", line 213, in fact_financials_tranform_load
    dwh_cursor.executemany(sql_insert, transformed_data)
psycopg2.errors.ForeignKeyViolation: insert or update on table "fact_fanancials" violates foreign key constraint "fact_fanancials_time_period_id_fkey"
DETAIL:  Key (time_period_id)=(Q1 2011) is not present in table "dim_time_period".

[2024-12-14T03:39:00.531+0000] {local_task_job_runner.py:266} INFO - Task exited with return code 1
[2024-12-14T03:39:00.598+0000] {taskinstance.py:3895} INFO - 0 downstream tasks scheduled from follow-on schedule check
[2024-12-14T03:39:00.609+0000] {local_task_job_runner.py:245} INFO - ::endgroup::
