[2024-12-09T09:59:37.737+0000] {local_task_job_runner.py:123} INFO - ::group::Pre task execution logs
[2024-12-09T09:59:37.863+0000] {taskinstance.py:2613} INFO - Dependencies all met for dep_context=non-requeueable deps ti=<TaskInstance: parallel_historycal_financial_reports.financial_reports.run_main_report manual__2024-12-09T09:59:26.770719+00:00 [queued]>
[2024-12-09T09:59:37.883+0000] {taskinstance.py:2613} INFO - Dependencies all met for dep_context=requeueable deps ti=<TaskInstance: parallel_historycal_financial_reports.financial_reports.run_main_report manual__2024-12-09T09:59:26.770719+00:00 [queued]>
[2024-12-09T09:59:37.884+0000] {taskinstance.py:2866} INFO - Starting attempt 1 of 1
[2024-12-09T09:59:37.910+0000] {taskinstance.py:2889} INFO - Executing <Task(PythonOperator): financial_reports.run_main_report> on 2024-12-09 09:59:26.770719+00:00
[2024-12-09T09:59:37.923+0000] {logging_mixin.py:190} WARNING - /usr/local/lib/python3.12/site-packages/airflow/task/task_runner/standard_task_runner.py:70 DeprecationWarning: This process (pid=260) is multi-threaded, use of fork() may lead to deadlocks in the child.
[2024-12-09T09:59:37.924+0000] {standard_task_runner.py:72} INFO - Started process 274 to run task
[2024-12-09T09:59:37.923+0000] {standard_task_runner.py:104} INFO - Running: ['airflow', 'tasks', 'run', 'parallel_historycal_financial_reports', 'financial_reports.run_main_report', 'manual__2024-12-09T09:59:26.770719+00:00', '--job-id', '199', '--raw', '--subdir', 'DAGS_FOLDER/Extract_history_financial_data.py', '--cfg-path', '/tmp/tmpvebktllf']
[2024-12-09T09:59:37.944+0000] {standard_task_runner.py:105} INFO - Job 199: Subtask financial_reports.run_main_report
[2024-12-09T09:59:38.292+0000] {task_command.py:467} INFO - Running <TaskInstance: parallel_historycal_financial_reports.financial_reports.run_main_report manual__2024-12-09T09:59:26.770719+00:00 [running]> on host 1ce88e57b286
[2024-12-09T09:59:39.357+0000] {taskinstance.py:3132} INFO - Exporting env vars: AIRFLOW_CTX_DAG_OWNER='airflowDWH' AIRFLOW_CTX_DAG_ID='parallel_historycal_financial_reports' AIRFLOW_CTX_TASK_ID='financial_reports.run_main_report' AIRFLOW_CTX_EXECUTION_DATE='2024-12-09T09:59:26.770719+00:00' AIRFLOW_CTX_TRY_NUMBER='1' AIRFLOW_CTX_DAG_RUN_ID='manual__2024-12-09T09:59:26.770719+00:00'
[2024-12-09T09:59:39.359+0000] {taskinstance.py:731} INFO - ::endgroup::
[2024-12-09T10:00:17.220+0000] {taskinstance.py:3311} ERROR - Task failed with exception
Traceback (most recent call last):
  File "/usr/local/lib/python3.12/site-packages/airflow/models/taskinstance.py", line 767, in _execute_task
    result = _execute_callable(context=context, **execute_callable_kwargs)
             ^^^^^^^^^^^^^^^^^^^^^^^^^^^^^^^^^^^^^^^^^^^^^^^^^^^^^^^^^^^^^
  File "/usr/local/lib/python3.12/site-packages/airflow/models/taskinstance.py", line 733, in _execute_callable
    return ExecutionCallableRunner(
           ^^^^^^^^^^^^^^^^^^^^^^^^
  File "/usr/local/lib/python3.12/site-packages/airflow/utils/operator_helpers.py", line 252, in run
    return self.func(*args, **kwargs)
           ^^^^^^^^^^^^^^^^^^^^^^^^^^
  File "/usr/local/lib/python3.12/site-packages/airflow/models/baseoperator.py", line 417, in wrapper
    return func(self, *args, **kwargs)
           ^^^^^^^^^^^^^^^^^^^^^^^^^^^
  File "/usr/local/lib/python3.12/site-packages/airflow/operators/python.py", line 238, in execute
    return_value = self.execute_callable()
                   ^^^^^^^^^^^^^^^^^^^^^^^
  File "/usr/local/lib/python3.12/site-packages/airflow/operators/python.py", line 256, in execute_callable
    return runner.run(*self.op_args, **self.op_kwargs)
           ^^^^^^^^^^^^^^^^^^^^^^^^^^^^^^^^^^^^^^^^^^^
  File "/usr/local/lib/python3.12/site-packages/airflow/utils/operator_helpers.py", line 252, in run
    return self.func(*args, **kwargs)
           ^^^^^^^^^^^^^^^^^^^^^^^^^^
  File "/opt/Tasks/HistoricalData/company_financial.py", line 26, in main_report
    select_option_Xpath(driver, "(//div[contains(@class,'list-filter')]//button)[1]")
  File "/opt/ScrapingPackage/navigation.py", line 14, in select_option_Xpath
    option = WebDriverWait(driver, 60).until(
             ^^^^^^^^^^^^^^^^^^^^^^^^^^^^^^^^
  File "/usr/local/lib/python3.12/site-packages/selenium/webdriver/support/wait.py", line 86, in until
    value = method(self._driver)
            ^^^^^^^^^^^^^^^^^^^^
  File "/usr/local/lib/python3.12/site-packages/selenium/webdriver/support/expected_conditions.py", line 355, in _predicate
    target = visibility_of(target)(driver)
             ^^^^^^^^^^^^^^^^^^^^^^^^^^^^^
  File "/usr/local/lib/python3.12/site-packages/selenium/webdriver/support/expected_conditions.py", line 168, in _predicate
    return _element_if_visible(element)
           ^^^^^^^^^^^^^^^^^^^^^^^^^^^^
  File "/usr/local/lib/python3.12/site-packages/selenium/webdriver/support/expected_conditions.py", line 174, in _element_if_visible
    return element if element.is_displayed() == visibility else False
                      ^^^^^^^^^^^^^^^^^^^^^^
  File "/usr/local/lib/python3.12/site-packages/selenium/webdriver/remote/webelement.py", line 251, in is_displayed
    return self.parent.execute_script(f"/* isDisplayed */return ({isDisplayed_js}).apply(null, arguments);", self)
           ^^^^^^^^^^^^^^^^^^^^^^^^^^^^^^^^^^^^^^^^^^^^^^^^^^^^^^^^^^^^^^^^^^^^^^^^^^^^^^^^^^^^^^^^^^^^^^^^^^^^^^^
  File "/usr/local/lib/python3.12/site-packages/selenium/webdriver/remote/webdriver.py", line 404, in execute_script
    return self.execute(command, {"script": script, "args": converted_args})["value"]
           ^^^^^^^^^^^^^^^^^^^^^^^^^^^^^^^^^^^^^^^^^^^^^^^^^^^^^^^^^^^^^^^^^
  File "/usr/local/lib/python3.12/site-packages/selenium/webdriver/remote/webdriver.py", line 344, in execute
    self.error_handler.check_response(response)
  File "/usr/local/lib/python3.12/site-packages/selenium/webdriver/remote/errorhandler.py", line 229, in check_response
    raise exception_class(message, screen, stacktrace)
selenium.common.exceptions.StaleElementReferenceException: Message: stale element reference: stale element not found
  (Session info: chrome=131.0.6778.85); For documentation on this error, please visit: https://www.selenium.dev/documentation/webdriver/troubleshooting/errors#stale-element-reference-exception
Stacktrace:
#0 0x563890abd31a <unknown>
#1 0x5638905d36e0 <unknown>
#2 0x5638905e4fbb <unknown>
#3 0x5638905e3d45 <unknown>
#4 0x5638905d9d39 <unknown>
#5 0x5638905d9e65 <unknown>
#6 0x5638905d80a0 <unknown>
#7 0x5638905dbc3e <unknown>
#8 0x563890665f6c <unknown>
#9 0x563890646462 <unknown>
#10 0x563890664ed7 <unknown>
#11 0x563890646203 <unknown>
#12 0x563890614cc0 <unknown>
#13 0x563890615c9e <unknown>
#14 0x563890a8ad0b <unknown>
#15 0x563890a8ec92 <unknown>
#16 0x563890a77b3c <unknown>
#17 0x563890a8f807 <unknown>
#18 0x563890a5d0df <unknown>
#19 0x563890aac578 <unknown>
#20 0x563890aac740 <unknown>
#21 0x563890abc196 <unknown>
#22 0x7ff9ef702a94 <unknown>
#23 0x7ff9ef78fc3c <unknown>

[2024-12-09T10:00:17.387+0000] {taskinstance.py:1225} INFO - Marking task as FAILED. dag_id=parallel_historycal_financial_reports, task_id=financial_reports.run_main_report, run_id=manual__2024-12-09T09:59:26.770719+00:00, execution_date=20241209T095926, start_date=20241209T095937, end_date=20241209T100017
[2024-12-09T10:00:17.784+0000] {taskinstance.py:340} INFO - ::group::Post task execution logs
[2024-12-09T10:00:17.789+0000] {standard_task_runner.py:124} ERROR - Failed to execute job 199 for task financial_reports.run_main_report (Message: stale element reference: stale element not found
  (Session info: chrome=131.0.6778.85); For documentation on this error, please visit: https://www.selenium.dev/documentation/webdriver/troubleshooting/errors#stale-element-reference-exception
Stacktrace:
#0 0x563890abd31a <unknown>
#1 0x5638905d36e0 <unknown>
#2 0x5638905e4fbb <unknown>
#3 0x5638905e3d45 <unknown>
#4 0x5638905d9d39 <unknown>
#5 0x5638905d9e65 <unknown>
#6 0x5638905d80a0 <unknown>
#7 0x5638905dbc3e <unknown>
#8 0x563890665f6c <unknown>
#9 0x563890646462 <unknown>
#10 0x563890664ed7 <unknown>
#11 0x563890646203 <unknown>
#12 0x563890614cc0 <unknown>
#13 0x563890615c9e <unknown>
#14 0x563890a8ad0b <unknown>
#15 0x563890a8ec92 <unknown>
#16 0x563890a77b3c <unknown>
#17 0x563890a8f807 <unknown>
#18 0x563890a5d0df <unknown>
#19 0x563890aac578 <unknown>
#20 0x563890aac740 <unknown>
#21 0x563890abc196 <unknown>
#22 0x7ff9ef702a94 <unknown>
#23 0x7ff9ef78fc3c <unknown>
; 274)
Traceback (most recent call last):
  File "/usr/local/lib/python3.12/site-packages/airflow/task/task_runner/standard_task_runner.py", line 117, in _start_by_fork
    ret = args.func(args, dag=self.dag)
          ^^^^^^^^^^^^^^^^^^^^^^^^^^^^^
  File "/usr/local/lib/python3.12/site-packages/airflow/cli/cli_config.py", line 49, in command
    return func(*args, **kwargs)
           ^^^^^^^^^^^^^^^^^^^^^
  File "/usr/local/lib/python3.12/site-packages/airflow/utils/cli.py", line 116, in wrapper
    return f(*args, **kwargs)
           ^^^^^^^^^^^^^^^^^^
  File "/usr/local/lib/python3.12/site-packages/airflow/cli/commands/task_command.py", line 483, in task_run
    task_return_code = _run_task_by_selected_method(args, _dag, ti)
                       ^^^^^^^^^^^^^^^^^^^^^^^^^^^^^^^^^^^^^^^^^^^^
  File "/usr/local/lib/python3.12/site-packages/airflow/cli/commands/task_command.py", line 256, in _run_task_by_selected_method
    return _run_raw_task(args, ti)
           ^^^^^^^^^^^^^^^^^^^^^^^
  File "/usr/local/lib/python3.12/site-packages/airflow/cli/commands/task_command.py", line 341, in _run_raw_task
    return ti._run_raw_task(
           ^^^^^^^^^^^^^^^^^
  File "/usr/local/lib/python3.12/site-packages/airflow/utils/session.py", line 97, in wrapper
    return func(*args, session=session, **kwargs)
           ^^^^^^^^^^^^^^^^^^^^^^^^^^^^^^^^^^^^^^
  File "/usr/local/lib/python3.12/site-packages/airflow/models/taskinstance.py", line 3005, in _run_raw_task
    return _run_raw_task(
           ^^^^^^^^^^^^^^
  File "/usr/local/lib/python3.12/site-packages/airflow/models/taskinstance.py", line 273, in _run_raw_task
    TaskInstance._execute_task_with_callbacks(
  File "/usr/local/lib/python3.12/site-packages/airflow/models/taskinstance.py", line 3159, in _execute_task_with_callbacks
    result = self._execute_task(context, task_orig)
             ^^^^^^^^^^^^^^^^^^^^^^^^^^^^^^^^^^^^^^
  File "/usr/local/lib/python3.12/site-packages/airflow/models/taskinstance.py", line 3183, in _execute_task
    return _execute_task(self, context, task_orig)
           ^^^^^^^^^^^^^^^^^^^^^^^^^^^^^^^^^^^^^^^
  File "/usr/local/lib/python3.12/site-packages/airflow/models/taskinstance.py", line 767, in _execute_task
    result = _execute_callable(context=context, **execute_callable_kwargs)
             ^^^^^^^^^^^^^^^^^^^^^^^^^^^^^^^^^^^^^^^^^^^^^^^^^^^^^^^^^^^^^
  File "/usr/local/lib/python3.12/site-packages/airflow/models/taskinstance.py", line 733, in _execute_callable
    return ExecutionCallableRunner(
           ^^^^^^^^^^^^^^^^^^^^^^^^
  File "/usr/local/lib/python3.12/site-packages/airflow/utils/operator_helpers.py", line 252, in run
    return self.func(*args, **kwargs)
           ^^^^^^^^^^^^^^^^^^^^^^^^^^
  File "/usr/local/lib/python3.12/site-packages/airflow/models/baseoperator.py", line 417, in wrapper
    return func(self, *args, **kwargs)
           ^^^^^^^^^^^^^^^^^^^^^^^^^^^
  File "/usr/local/lib/python3.12/site-packages/airflow/operators/python.py", line 238, in execute
    return_value = self.execute_callable()
                   ^^^^^^^^^^^^^^^^^^^^^^^
  File "/usr/local/lib/python3.12/site-packages/airflow/operators/python.py", line 256, in execute_callable
    return runner.run(*self.op_args, **self.op_kwargs)
           ^^^^^^^^^^^^^^^^^^^^^^^^^^^^^^^^^^^^^^^^^^^
  File "/usr/local/lib/python3.12/site-packages/airflow/utils/operator_helpers.py", line 252, in run
    return self.func(*args, **kwargs)
           ^^^^^^^^^^^^^^^^^^^^^^^^^^
  File "/opt/Tasks/HistoricalData/company_financial.py", line 26, in main_report
    select_option_Xpath(driver, "(//div[contains(@class,'list-filter')]//button)[1]")
  File "/opt/ScrapingPackage/navigation.py", line 14, in select_option_Xpath
    option = WebDriverWait(driver, 60).until(
             ^^^^^^^^^^^^^^^^^^^^^^^^^^^^^^^^
  File "/usr/local/lib/python3.12/site-packages/selenium/webdriver/support/wait.py", line 86, in until
    value = method(self._driver)
            ^^^^^^^^^^^^^^^^^^^^
  File "/usr/local/lib/python3.12/site-packages/selenium/webdriver/support/expected_conditions.py", line 355, in _predicate
    target = visibility_of(target)(driver)
             ^^^^^^^^^^^^^^^^^^^^^^^^^^^^^
  File "/usr/local/lib/python3.12/site-packages/selenium/webdriver/support/expected_conditions.py", line 168, in _predicate
    return _element_if_visible(element)
           ^^^^^^^^^^^^^^^^^^^^^^^^^^^^
  File "/usr/local/lib/python3.12/site-packages/selenium/webdriver/support/expected_conditions.py", line 174, in _element_if_visible
    return element if element.is_displayed() == visibility else False
                      ^^^^^^^^^^^^^^^^^^^^^^
  File "/usr/local/lib/python3.12/site-packages/selenium/webdriver/remote/webelement.py", line 251, in is_displayed
    return self.parent.execute_script(f"/* isDisplayed */return ({isDisplayed_js}).apply(null, arguments);", self)
           ^^^^^^^^^^^^^^^^^^^^^^^^^^^^^^^^^^^^^^^^^^^^^^^^^^^^^^^^^^^^^^^^^^^^^^^^^^^^^^^^^^^^^^^^^^^^^^^^^^^^^^^
  File "/usr/local/lib/python3.12/site-packages/selenium/webdriver/remote/webdriver.py", line 404, in execute_script
    return self.execute(command, {"script": script, "args": converted_args})["value"]
           ^^^^^^^^^^^^^^^^^^^^^^^^^^^^^^^^^^^^^^^^^^^^^^^^^^^^^^^^^^^^^^^^^
  File "/usr/local/lib/python3.12/site-packages/selenium/webdriver/remote/webdriver.py", line 344, in execute
    self.error_handler.check_response(response)
  File "/usr/local/lib/python3.12/site-packages/selenium/webdriver/remote/errorhandler.py", line 229, in check_response
    raise exception_class(message, screen, stacktrace)
selenium.common.exceptions.StaleElementReferenceException: Message: stale element reference: stale element not found
  (Session info: chrome=131.0.6778.85); For documentation on this error, please visit: https://www.selenium.dev/documentation/webdriver/troubleshooting/errors#stale-element-reference-exception
Stacktrace:
#0 0x563890abd31a <unknown>
#1 0x5638905d36e0 <unknown>
#2 0x5638905e4fbb <unknown>
#3 0x5638905e3d45 <unknown>
#4 0x5638905d9d39 <unknown>
#5 0x5638905d9e65 <unknown>
#6 0x5638905d80a0 <unknown>
#7 0x5638905dbc3e <unknown>
#8 0x563890665f6c <unknown>
#9 0x563890646462 <unknown>
#10 0x563890664ed7 <unknown>
#11 0x563890646203 <unknown>
#12 0x563890614cc0 <unknown>
#13 0x563890615c9e <unknown>
#14 0x563890a8ad0b <unknown>
#15 0x563890a8ec92 <unknown>
#16 0x563890a77b3c <unknown>
#17 0x563890a8f807 <unknown>
#18 0x563890a5d0df <unknown>
#19 0x563890aac578 <unknown>
#20 0x563890aac740 <unknown>
#21 0x563890abc196 <unknown>
#22 0x7ff9ef702a94 <unknown>
#23 0x7ff9ef78fc3c <unknown>

[2024-12-09T10:00:17.830+0000] {local_task_job_runner.py:266} INFO - Task exited with return code 1
[2024-12-09T10:00:18.018+0000] {standard_task_runner.py:217} INFO - Process not found (most likely exited), stop collecting metrics
[2024-12-09T10:00:18.118+0000] {taskinstance.py:3895} INFO - 0 downstream tasks scheduled from follow-on schedule check
[2024-12-09T10:00:18.134+0000] {local_task_job_runner.py:245} INFO - ::endgroup::
