[2024-12-12T14:17:42.518+0000] {local_task_job_runner.py:123} INFO - ::group::Pre task execution logs
[2024-12-12T14:17:42.583+0000] {taskinstance.py:2613} INFO - Dependencies all met for dep_context=non-requeueable deps ti=<TaskInstance: parallel_historical_price_with_group.process_groups.process_group_0 manual__2024-12-12T14:17:28.055359+00:00 [queued]>
[2024-12-12T14:17:42.602+0000] {taskinstance.py:2613} INFO - Dependencies all met for dep_context=requeueable deps ti=<TaskInstance: parallel_historical_price_with_group.process_groups.process_group_0 manual__2024-12-12T14:17:28.055359+00:00 [queued]>
[2024-12-12T14:17:42.603+0000] {taskinstance.py:2866} INFO - Starting attempt 1 of 1
[2024-12-12T14:17:42.680+0000] {taskinstance.py:2889} INFO - Executing <Task(PythonOperator): process_groups.process_group_0> on 2024-12-12 14:17:28.055359+00:00
[2024-12-12T14:17:42.698+0000] {logging_mixin.py:190} WARNING - /usr/local/lib/python3.12/site-packages/airflow/task/task_runner/standard_task_runner.py:70 DeprecationWarning: This process (pid=4346) is multi-threaded, use of fork() may lead to deadlocks in the child.
[2024-12-12T14:17:42.703+0000] {standard_task_runner.py:72} INFO - Started process 4370 to run task
[2024-12-12T14:17:42.788+0000] {standard_task_runner.py:104} INFO - Running: ['airflow', 'tasks', 'run', 'parallel_historical_price_with_group', 'process_groups.process_group_0', 'manual__2024-12-12T14:17:28.055359+00:00', '--job-id', '365', '--raw', '--subdir', 'DAGS_FOLDER/Extract_history_price_data.py', '--cfg-path', '/tmp/tmp126pkmk9']
[2024-12-12T14:17:42.796+0000] {standard_task_runner.py:105} INFO - Job 365: Subtask process_groups.process_group_0
[2024-12-12T14:17:43.352+0000] {task_command.py:467} INFO - Running <TaskInstance: parallel_historical_price_with_group.process_groups.process_group_0 manual__2024-12-12T14:17:28.055359+00:00 [running]> on host f1b774b5d57f
[2024-12-12T14:17:44.136+0000] {taskinstance.py:3132} INFO - Exporting env vars: AIRFLOW_CTX_DAG_OWNER='airflowDWH' AIRFLOW_CTX_DAG_ID='parallel_historical_price_with_group' AIRFLOW_CTX_TASK_ID='process_groups.process_group_0' AIRFLOW_CTX_EXECUTION_DATE='2024-12-12T14:17:28.055359+00:00' AIRFLOW_CTX_TRY_NUMBER='1' AIRFLOW_CTX_DAG_RUN_ID='manual__2024-12-12T14:17:28.055359+00:00'
[2024-12-12T14:17:44.143+0000] {taskinstance.py:731} INFO - ::endgroup::
[2024-12-12T14:17:46.838+0000] {data_explorer.py:64} WARNING - Thông tin niêm yết & giao dịch sẽ được truy xuất từ TCBS
[2024-12-12T14:17:47.882+0000] {data_explorer.py:64} WARNING - Thông tin niêm yết & giao dịch sẽ được truy xuất từ TCBS
[2024-12-12T14:17:48.800+0000] {data_explorer.py:64} WARNING - Thông tin niêm yết & giao dịch sẽ được truy xuất từ TCBS
[2024-12-12T14:17:49.869+0000] {data_explorer.py:64} WARNING - Thông tin niêm yết & giao dịch sẽ được truy xuất từ TCBS
[2024-12-12T14:17:51.015+0000] {data_explorer.py:64} WARNING - Thông tin niêm yết & giao dịch sẽ được truy xuất từ TCBS
[2024-12-12T14:17:52.407+0000] {data_explorer.py:64} WARNING - Thông tin niêm yết & giao dịch sẽ được truy xuất từ TCBS
[2024-12-12T14:17:53.378+0000] {data_explorer.py:64} WARNING - Thông tin niêm yết & giao dịch sẽ được truy xuất từ TCBS
[2024-12-12T14:17:54.725+0000] {data_explorer.py:64} WARNING - Thông tin niêm yết & giao dịch sẽ được truy xuất từ TCBS
[2024-12-12T14:17:55.932+0000] {data_explorer.py:64} WARNING - Thông tin niêm yết & giao dịch sẽ được truy xuất từ TCBS
[2024-12-12T14:17:57.493+0000] {data_explorer.py:64} WARNING - Thông tin niêm yết & giao dịch sẽ được truy xuất từ TCBS
[2024-12-12T14:18:07.858+0000] {taskinstance.py:3311} ERROR - Task failed with exception
Traceback (most recent call last):
  File "/usr/local/lib/python3.12/site-packages/urllib3/connection.py", line 199, in _new_conn
    sock = connection.create_connection(
           ^^^^^^^^^^^^^^^^^^^^^^^^^^^^^
  File "/usr/local/lib/python3.12/site-packages/urllib3/util/connection.py", line 60, in create_connection
    for res in socket.getaddrinfo(host, port, family, socket.SOCK_STREAM):
               ^^^^^^^^^^^^^^^^^^^^^^^^^^^^^^^^^^^^^^^^^^^^^^^^^^^^^^^^^^
  File "/usr/local/lib/python3.12/socket.py", line 976, in getaddrinfo
    for res in _socket.getaddrinfo(host, port, family, type, proto, flags):
               ^^^^^^^^^^^^^^^^^^^^^^^^^^^^^^^^^^^^^^^^^^^^^^^^^^^^^^^^^^^
socket.gaierror: [Errno -3] Temporary failure in name resolution

The above exception was the direct cause of the following exception:

Traceback (most recent call last):
  File "/usr/local/lib/python3.12/site-packages/urllib3/connectionpool.py", line 789, in urlopen
    response = self._make_request(
               ^^^^^^^^^^^^^^^^^^^
  File "/usr/local/lib/python3.12/site-packages/urllib3/connectionpool.py", line 490, in _make_request
    raise new_e
  File "/usr/local/lib/python3.12/site-packages/urllib3/connectionpool.py", line 466, in _make_request
    self._validate_conn(conn)
  File "/usr/local/lib/python3.12/site-packages/urllib3/connectionpool.py", line 1095, in _validate_conn
    conn.connect()
  File "/usr/local/lib/python3.12/site-packages/urllib3/connection.py", line 693, in connect
    self.sock = sock = self._new_conn()
                       ^^^^^^^^^^^^^^^^
  File "/usr/local/lib/python3.12/site-packages/urllib3/connection.py", line 206, in _new_conn
    raise NameResolutionError(self.host, self, e) from e
urllib3.exceptions.NameResolutionError: <urllib3.connection.HTTPSConnection object at 0x7f09c1e43440>: Failed to resolve 'trading.vietcap.com.vn' ([Errno -3] Temporary failure in name resolution)

The above exception was the direct cause of the following exception:

Traceback (most recent call last):
  File "/usr/local/lib/python3.12/site-packages/requests/adapters.py", line 667, in send
    resp = conn.urlopen(
           ^^^^^^^^^^^^^
  File "/usr/local/lib/python3.12/site-packages/urllib3/connectionpool.py", line 843, in urlopen
    retries = retries.increment(
              ^^^^^^^^^^^^^^^^^^
  File "/usr/local/lib/python3.12/site-packages/urllib3/util/retry.py", line 519, in increment
    raise MaxRetryError(_pool, url, reason) from reason  # type: ignore[arg-type]
    ^^^^^^^^^^^^^^^^^^^^^^^^^^^^^^^^^^^^^^^^^^^^^^^^^^^
urllib3.exceptions.MaxRetryError: HTTPSConnectionPool(host='trading.vietcap.com.vn', port=443): Max retries exceeded with url: /api/chart/OHLCChart/gap (Caused by NameResolutionError("<urllib3.connection.HTTPSConnection object at 0x7f09c1e43440>: Failed to resolve 'trading.vietcap.com.vn' ([Errno -3] Temporary failure in name resolution)"))

During handling of the above exception, another exception occurred:

Traceback (most recent call last):
  File "/usr/local/lib/python3.12/site-packages/airflow/models/taskinstance.py", line 767, in _execute_task
    result = _execute_callable(context=context, **execute_callable_kwargs)
             ^^^^^^^^^^^^^^^^^^^^^^^^^^^^^^^^^^^^^^^^^^^^^^^^^^^^^^^^^^^^^
  File "/usr/local/lib/python3.12/site-packages/airflow/models/taskinstance.py", line 733, in _execute_callable
    return ExecutionCallableRunner(
           ^^^^^^^^^^^^^^^^^^^^^^^^
  File "/usr/local/lib/python3.12/site-packages/airflow/utils/operator_helpers.py", line 252, in run
    return self.func(*args, **kwargs)
           ^^^^^^^^^^^^^^^^^^^^^^^^^^
  File "/usr/local/lib/python3.12/site-packages/airflow/models/baseoperator.py", line 417, in wrapper
    return func(self, *args, **kwargs)
           ^^^^^^^^^^^^^^^^^^^^^^^^^^^
  File "/usr/local/lib/python3.12/site-packages/airflow/operators/python.py", line 238, in execute
    return_value = self.execute_callable()
                   ^^^^^^^^^^^^^^^^^^^^^^^
  File "/usr/local/lib/python3.12/site-packages/airflow/operators/python.py", line 256, in execute_callable
    return runner.run(*self.op_args, **self.op_kwargs)
           ^^^^^^^^^^^^^^^^^^^^^^^^^^^^^^^^^^^^^^^^^^^
  File "/usr/local/lib/python3.12/site-packages/airflow/utils/operator_helpers.py", line 252, in run
    return self.func(*args, **kwargs)
           ^^^^^^^^^^^^^^^^^^^^^^^^^^
  File "/opt/airflow/dags/Extract_history_price_data.py", line 27, in process_group
    result = historical_price(stock_codes)
             ^^^^^^^^^^^^^^^^^^^^^^^^^^^^^
  File "/opt/Tasks/extract/HistoricalData/Historical_price_stock.py", line 12, in historical_price
    HisPriceDF = stock.quote.history(start='2015-01-01', end='2024-12-7')
                 ^^^^^^^^^^^^^^^^^^^^^^^^^^^^^^^^^^^^^^^^^^^^^^^^^^^^^^^^
  File "/usr/local/lib/python3.12/site-packages/vnstock3/common/data/data_explorer.py", line 127, in history
    return self.data_source.history(**kwargs)
           ^^^^^^^^^^^^^^^^^^^^^^^^^^^^^^^^^^
  File "/usr/local/lib/python3.12/site-packages/vnstock3/explorer/vci/quote.py", line 111, in history
    response = requests.post(url, headers=self.headers, data=payload)
               ^^^^^^^^^^^^^^^^^^^^^^^^^^^^^^^^^^^^^^^^^^^^^^^^^^^^^^
  File "/usr/local/lib/python3.12/site-packages/requests/api.py", line 115, in post
    return request("post", url, data=data, json=json, **kwargs)
           ^^^^^^^^^^^^^^^^^^^^^^^^^^^^^^^^^^^^^^^^^^^^^^^^^^^^
  File "/usr/local/lib/python3.12/site-packages/requests/api.py", line 59, in request
    return session.request(method=method, url=url, **kwargs)
           ^^^^^^^^^^^^^^^^^^^^^^^^^^^^^^^^^^^^^^^^^^^^^^^^^
  File "/usr/local/lib/python3.12/site-packages/requests/sessions.py", line 589, in request
    resp = self.send(prep, **send_kwargs)
           ^^^^^^^^^^^^^^^^^^^^^^^^^^^^^^
  File "/usr/local/lib/python3.12/site-packages/requests/sessions.py", line 703, in send
    r = adapter.send(request, **kwargs)
        ^^^^^^^^^^^^^^^^^^^^^^^^^^^^^^^
  File "/usr/local/lib/python3.12/site-packages/requests/adapters.py", line 700, in send
    raise ConnectionError(e, request=request)
requests.exceptions.ConnectionError: HTTPSConnectionPool(host='trading.vietcap.com.vn', port=443): Max retries exceeded with url: /api/chart/OHLCChart/gap (Caused by NameResolutionError("<urllib3.connection.HTTPSConnection object at 0x7f09c1e43440>: Failed to resolve 'trading.vietcap.com.vn' ([Errno -3] Temporary failure in name resolution)"))
[2024-12-12T14:18:10.972+0000] {taskinstance.py:1225} INFO - Marking task as FAILED. dag_id=parallel_historical_price_with_group, task_id=process_groups.process_group_0, run_id=manual__2024-12-12T14:17:28.055359+00:00, execution_date=20241212T141728, start_date=20241212T141742, end_date=20241212T141810
[2024-12-12T14:18:10.989+0000] {job.py:229} INFO - Heartbeat recovered after 18.01 seconds
[2024-12-12T14:18:11.265+0000] {taskinstance.py:340} INFO - ::group::Post task execution logs
[2024-12-12T14:18:11.266+0000] {standard_task_runner.py:124} ERROR - Failed to execute job 365 for task process_groups.process_group_0 (HTTPSConnectionPool(host='trading.vietcap.com.vn', port=443): Max retries exceeded with url: /api/chart/OHLCChart/gap (Caused by NameResolutionError("<urllib3.connection.HTTPSConnection object at 0x7f09c1e43440>: Failed to resolve 'trading.vietcap.com.vn' ([Errno -3] Temporary failure in name resolution)")); 4370)
Traceback (most recent call last):
  File "/usr/local/lib/python3.12/site-packages/urllib3/connection.py", line 199, in _new_conn
    sock = connection.create_connection(
           ^^^^^^^^^^^^^^^^^^^^^^^^^^^^^
  File "/usr/local/lib/python3.12/site-packages/urllib3/util/connection.py", line 60, in create_connection
    for res in socket.getaddrinfo(host, port, family, socket.SOCK_STREAM):
               ^^^^^^^^^^^^^^^^^^^^^^^^^^^^^^^^^^^^^^^^^^^^^^^^^^^^^^^^^^
  File "/usr/local/lib/python3.12/socket.py", line 976, in getaddrinfo
    for res in _socket.getaddrinfo(host, port, family, type, proto, flags):
               ^^^^^^^^^^^^^^^^^^^^^^^^^^^^^^^^^^^^^^^^^^^^^^^^^^^^^^^^^^^
socket.gaierror: [Errno -3] Temporary failure in name resolution

The above exception was the direct cause of the following exception:

Traceback (most recent call last):
  File "/usr/local/lib/python3.12/site-packages/urllib3/connectionpool.py", line 789, in urlopen
    response = self._make_request(
               ^^^^^^^^^^^^^^^^^^^
  File "/usr/local/lib/python3.12/site-packages/urllib3/connectionpool.py", line 490, in _make_request
    raise new_e
  File "/usr/local/lib/python3.12/site-packages/urllib3/connectionpool.py", line 466, in _make_request
    self._validate_conn(conn)
  File "/usr/local/lib/python3.12/site-packages/urllib3/connectionpool.py", line 1095, in _validate_conn
    conn.connect()
  File "/usr/local/lib/python3.12/site-packages/urllib3/connection.py", line 693, in connect
    self.sock = sock = self._new_conn()
                       ^^^^^^^^^^^^^^^^
  File "/usr/local/lib/python3.12/site-packages/urllib3/connection.py", line 206, in _new_conn
    raise NameResolutionError(self.host, self, e) from e
urllib3.exceptions.NameResolutionError: <urllib3.connection.HTTPSConnection object at 0x7f09c1e43440>: Failed to resolve 'trading.vietcap.com.vn' ([Errno -3] Temporary failure in name resolution)

The above exception was the direct cause of the following exception:

Traceback (most recent call last):
  File "/usr/local/lib/python3.12/site-packages/requests/adapters.py", line 667, in send
    resp = conn.urlopen(
           ^^^^^^^^^^^^^
  File "/usr/local/lib/python3.12/site-packages/urllib3/connectionpool.py", line 843, in urlopen
    retries = retries.increment(
              ^^^^^^^^^^^^^^^^^^
  File "/usr/local/lib/python3.12/site-packages/urllib3/util/retry.py", line 519, in increment
    raise MaxRetryError(_pool, url, reason) from reason  # type: ignore[arg-type]
    ^^^^^^^^^^^^^^^^^^^^^^^^^^^^^^^^^^^^^^^^^^^^^^^^^^^
urllib3.exceptions.MaxRetryError: HTTPSConnectionPool(host='trading.vietcap.com.vn', port=443): Max retries exceeded with url: /api/chart/OHLCChart/gap (Caused by NameResolutionError("<urllib3.connection.HTTPSConnection object at 0x7f09c1e43440>: Failed to resolve 'trading.vietcap.com.vn' ([Errno -3] Temporary failure in name resolution)"))

During handling of the above exception, another exception occurred:

Traceback (most recent call last):
  File "/usr/local/lib/python3.12/site-packages/airflow/task/task_runner/standard_task_runner.py", line 117, in _start_by_fork
    ret = args.func(args, dag=self.dag)
          ^^^^^^^^^^^^^^^^^^^^^^^^^^^^^
  File "/usr/local/lib/python3.12/site-packages/airflow/cli/cli_config.py", line 49, in command
    return func(*args, **kwargs)
           ^^^^^^^^^^^^^^^^^^^^^
  File "/usr/local/lib/python3.12/site-packages/airflow/utils/cli.py", line 116, in wrapper
    return f(*args, **kwargs)
           ^^^^^^^^^^^^^^^^^^
  File "/usr/local/lib/python3.12/site-packages/airflow/cli/commands/task_command.py", line 483, in task_run
    task_return_code = _run_task_by_selected_method(args, _dag, ti)
                       ^^^^^^^^^^^^^^^^^^^^^^^^^^^^^^^^^^^^^^^^^^^^
  File "/usr/local/lib/python3.12/site-packages/airflow/cli/commands/task_command.py", line 256, in _run_task_by_selected_method
    return _run_raw_task(args, ti)
           ^^^^^^^^^^^^^^^^^^^^^^^
  File "/usr/local/lib/python3.12/site-packages/airflow/cli/commands/task_command.py", line 341, in _run_raw_task
    return ti._run_raw_task(
           ^^^^^^^^^^^^^^^^^
  File "/usr/local/lib/python3.12/site-packages/airflow/utils/session.py", line 97, in wrapper
    return func(*args, session=session, **kwargs)
           ^^^^^^^^^^^^^^^^^^^^^^^^^^^^^^^^^^^^^^
  File "/usr/local/lib/python3.12/site-packages/airflow/models/taskinstance.py", line 3005, in _run_raw_task
    return _run_raw_task(
           ^^^^^^^^^^^^^^
  File "/usr/local/lib/python3.12/site-packages/airflow/models/taskinstance.py", line 273, in _run_raw_task
    TaskInstance._execute_task_with_callbacks(
  File "/usr/local/lib/python3.12/site-packages/airflow/models/taskinstance.py", line 3159, in _execute_task_with_callbacks
    result = self._execute_task(context, task_orig)
             ^^^^^^^^^^^^^^^^^^^^^^^^^^^^^^^^^^^^^^
  File "/usr/local/lib/python3.12/site-packages/airflow/models/taskinstance.py", line 3183, in _execute_task
    return _execute_task(self, context, task_orig)
           ^^^^^^^^^^^^^^^^^^^^^^^^^^^^^^^^^^^^^^^
  File "/usr/local/lib/python3.12/site-packages/airflow/models/taskinstance.py", line 767, in _execute_task
    result = _execute_callable(context=context, **execute_callable_kwargs)
             ^^^^^^^^^^^^^^^^^^^^^^^^^^^^^^^^^^^^^^^^^^^^^^^^^^^^^^^^^^^^^
  File "/usr/local/lib/python3.12/site-packages/airflow/models/taskinstance.py", line 733, in _execute_callable
    return ExecutionCallableRunner(
           ^^^^^^^^^^^^^^^^^^^^^^^^
  File "/usr/local/lib/python3.12/site-packages/airflow/utils/operator_helpers.py", line 252, in run
    return self.func(*args, **kwargs)
           ^^^^^^^^^^^^^^^^^^^^^^^^^^
  File "/usr/local/lib/python3.12/site-packages/airflow/models/baseoperator.py", line 417, in wrapper
    return func(self, *args, **kwargs)
           ^^^^^^^^^^^^^^^^^^^^^^^^^^^
  File "/usr/local/lib/python3.12/site-packages/airflow/operators/python.py", line 238, in execute
    return_value = self.execute_callable()
                   ^^^^^^^^^^^^^^^^^^^^^^^
  File "/usr/local/lib/python3.12/site-packages/airflow/operators/python.py", line 256, in execute_callable
    return runner.run(*self.op_args, **self.op_kwargs)
           ^^^^^^^^^^^^^^^^^^^^^^^^^^^^^^^^^^^^^^^^^^^
  File "/usr/local/lib/python3.12/site-packages/airflow/utils/operator_helpers.py", line 252, in run
    return self.func(*args, **kwargs)
           ^^^^^^^^^^^^^^^^^^^^^^^^^^
  File "/opt/airflow/dags/Extract_history_price_data.py", line 27, in process_group
    result = historical_price(stock_codes)
             ^^^^^^^^^^^^^^^^^^^^^^^^^^^^^
  File "/opt/Tasks/extract/HistoricalData/Historical_price_stock.py", line 12, in historical_price
    HisPriceDF = stock.quote.history(start='2015-01-01', end='2024-12-7')
                 ^^^^^^^^^^^^^^^^^^^^^^^^^^^^^^^^^^^^^^^^^^^^^^^^^^^^^^^^
  File "/usr/local/lib/python3.12/site-packages/vnstock3/common/data/data_explorer.py", line 127, in history
    return self.data_source.history(**kwargs)
           ^^^^^^^^^^^^^^^^^^^^^^^^^^^^^^^^^^
  File "/usr/local/lib/python3.12/site-packages/vnstock3/explorer/vci/quote.py", line 111, in history
    response = requests.post(url, headers=self.headers, data=payload)
               ^^^^^^^^^^^^^^^^^^^^^^^^^^^^^^^^^^^^^^^^^^^^^^^^^^^^^^
  File "/usr/local/lib/python3.12/site-packages/requests/api.py", line 115, in post
    return request("post", url, data=data, json=json, **kwargs)
           ^^^^^^^^^^^^^^^^^^^^^^^^^^^^^^^^^^^^^^^^^^^^^^^^^^^^
  File "/usr/local/lib/python3.12/site-packages/requests/api.py", line 59, in request
    return session.request(method=method, url=url, **kwargs)
           ^^^^^^^^^^^^^^^^^^^^^^^^^^^^^^^^^^^^^^^^^^^^^^^^^
  File "/usr/local/lib/python3.12/site-packages/requests/sessions.py", line 589, in request
    resp = self.send(prep, **send_kwargs)
           ^^^^^^^^^^^^^^^^^^^^^^^^^^^^^^
  File "/usr/local/lib/python3.12/site-packages/requests/sessions.py", line 703, in send
    r = adapter.send(request, **kwargs)
        ^^^^^^^^^^^^^^^^^^^^^^^^^^^^^^^
  File "/usr/local/lib/python3.12/site-packages/requests/adapters.py", line 700, in send
    raise ConnectionError(e, request=request)
requests.exceptions.ConnectionError: HTTPSConnectionPool(host='trading.vietcap.com.vn', port=443): Max retries exceeded with url: /api/chart/OHLCChart/gap (Caused by NameResolutionError("<urllib3.connection.HTTPSConnection object at 0x7f09c1e43440>: Failed to resolve 'trading.vietcap.com.vn' ([Errno -3] Temporary failure in name resolution)"))
[2024-12-12T14:18:11.390+0000] {local_task_job_runner.py:266} INFO - Task exited with return code 1
[2024-12-12T14:18:11.802+0000] {taskinstance.py:3895} INFO - 0 downstream tasks scheduled from follow-on schedule check
[2024-12-12T14:18:11.823+0000] {local_task_job_runner.py:245} INFO - ::endgroup::
