[2024-12-09T09:40:13.878+0000] {local_task_job_runner.py:123} INFO - ::group::Pre task execution logs
[2024-12-09T09:40:14.011+0000] {taskinstance.py:2613} INFO - Dependencies all met for dep_context=non-requeueable deps ti=<TaskInstance: parallel_historycal_financial_reports.financial_reports.run_main_report_1 manual__2024-12-09T09:40:03.368951+00:00 [queued]>
[2024-12-09T09:40:14.045+0000] {taskinstance.py:2613} INFO - Dependencies all met for dep_context=requeueable deps ti=<TaskInstance: parallel_historycal_financial_reports.financial_reports.run_main_report_1 manual__2024-12-09T09:40:03.368951+00:00 [queued]>
[2024-12-09T09:40:14.046+0000] {taskinstance.py:2866} INFO - Starting attempt 1 of 1
[2024-12-09T09:40:14.137+0000] {taskinstance.py:2889} INFO - Executing <Task(PythonOperator): financial_reports.run_main_report_1> on 2024-12-09 09:40:03.368951+00:00
[2024-12-09T09:40:14.170+0000] {logging_mixin.py:190} WARNING - /usr/local/lib/python3.12/site-packages/airflow/task/task_runner/standard_task_runner.py:70 DeprecationWarning: This process (pid=5968) is multi-threaded, use of fork() may lead to deadlocks in the child.
[2024-12-09T09:40:14.212+0000] {standard_task_runner.py:72} INFO - Started process 5983 to run task
[2024-12-09T09:40:14.201+0000] {standard_task_runner.py:104} INFO - Running: ['airflow', 'tasks', 'run', 'parallel_historycal_financial_reports', 'financial_reports.run_main_report_1', 'manual__2024-12-09T09:40:03.368951+00:00', '--job-id', '196', '--raw', '--subdir', 'DAGS_FOLDER/Extract_history_financial_data.py', '--cfg-path', '/tmp/tmp1f3zlkxv']
[2024-12-09T09:40:14.225+0000] {standard_task_runner.py:105} INFO - Job 196: Subtask financial_reports.run_main_report_1
[2024-12-09T09:40:14.632+0000] {task_command.py:467} INFO - Running <TaskInstance: parallel_historycal_financial_reports.financial_reports.run_main_report_1 manual__2024-12-09T09:40:03.368951+00:00 [running]> on host 307e002f4b90
[2024-12-09T09:40:14.887+0000] {taskinstance.py:3132} INFO - Exporting env vars: AIRFLOW_CTX_DAG_OWNER='airflowDWH' AIRFLOW_CTX_DAG_ID='parallel_historycal_financial_reports' AIRFLOW_CTX_TASK_ID='financial_reports.run_main_report_1' AIRFLOW_CTX_EXECUTION_DATE='2024-12-09T09:40:03.368951+00:00' AIRFLOW_CTX_TRY_NUMBER='1' AIRFLOW_CTX_DAG_RUN_ID='manual__2024-12-09T09:40:03.368951+00:00'
[2024-12-09T09:40:14.889+0000] {taskinstance.py:731} INFO - ::endgroup::
[2024-12-09T09:44:52.722+0000] {job.py:239} ERROR - Job heartbeat failed with error
Traceback (most recent call last):
  File "/usr/local/lib/python3.12/site-packages/sqlalchemy/engine/base.py", line 3371, in _wrap_pool_connect
    return fn()
           ^^^^
  File "/usr/local/lib/python3.12/site-packages/sqlalchemy/pool/base.py", line 327, in connect
    return _ConnectionFairy._checkout(self)
           ^^^^^^^^^^^^^^^^^^^^^^^^^^^^^^^^
  File "/usr/local/lib/python3.12/site-packages/sqlalchemy/pool/base.py", line 894, in _checkout
    fairy = _ConnectionRecord.checkout(pool)
            ^^^^^^^^^^^^^^^^^^^^^^^^^^^^^^^^
  File "/usr/local/lib/python3.12/site-packages/sqlalchemy/pool/base.py", line 493, in checkout
    rec = pool._do_get()
          ^^^^^^^^^^^^^^
  File "/usr/local/lib/python3.12/site-packages/sqlalchemy/pool/impl.py", line 256, in _do_get
    return self._create_connection()
           ^^^^^^^^^^^^^^^^^^^^^^^^^
  File "/usr/local/lib/python3.12/site-packages/sqlalchemy/pool/base.py", line 273, in _create_connection
    return _ConnectionRecord(self)
           ^^^^^^^^^^^^^^^^^^^^^^^
  File "/usr/local/lib/python3.12/site-packages/sqlalchemy/pool/base.py", line 388, in __init__
    self.__connect()
  File "/usr/local/lib/python3.12/site-packages/sqlalchemy/pool/base.py", line 690, in __connect
    with util.safe_reraise():
         ^^^^^^^^^^^^^^^^^^^
  File "/usr/local/lib/python3.12/site-packages/sqlalchemy/util/langhelpers.py", line 70, in __exit__
    compat.raise_(
  File "/usr/local/lib/python3.12/site-packages/sqlalchemy/util/compat.py", line 211, in raise_
    raise exception
  File "/usr/local/lib/python3.12/site-packages/sqlalchemy/pool/base.py", line 686, in __connect
    self.dbapi_connection = connection = pool._invoke_creator(self)
                                         ^^^^^^^^^^^^^^^^^^^^^^^^^^
  File "/usr/local/lib/python3.12/site-packages/sqlalchemy/engine/create.py", line 574, in connect
    return dialect.connect(*cargs, **cparams)
           ^^^^^^^^^^^^^^^^^^^^^^^^^^^^^^^^^^
  File "/usr/local/lib/python3.12/site-packages/sqlalchemy/engine/default.py", line 598, in connect
    return self.dbapi.connect(*cargs, **cparams)
           ^^^^^^^^^^^^^^^^^^^^^^^^^^^^^^^^^^^^^
  File "/usr/local/lib/python3.12/site-packages/psycopg2/__init__.py", line 122, in connect
    conn = _connect(dsn, connection_factory=connection_factory, **kwasync)
           ^^^^^^^^^^^^^^^^^^^^^^^^^^^^^^^^^^^^^^^^^^^^^^^^^^^^^^^^^^^^^^^
psycopg2.OperationalError: could not translate host name "host.docker.internal" to address: Temporary failure in name resolution


The above exception was the direct cause of the following exception:

Traceback (most recent call last):
  File "/usr/local/lib/python3.12/site-packages/airflow/jobs/job.py", line 207, in heartbeat
    self._merge_from(Job._fetch_from_db(self, session))
                     ^^^^^^^^^^^^^^^^^^^^^^^^^^^^^^^^^
  File "/usr/local/lib/python3.12/site-packages/airflow/api_internal/internal_api_call.py", line 166, in wrapper
    return func(*args, **kwargs)
           ^^^^^^^^^^^^^^^^^^^^^
  File "/usr/local/lib/python3.12/site-packages/airflow/utils/session.py", line 94, in wrapper
    return func(*args, **kwargs)
           ^^^^^^^^^^^^^^^^^^^^^
  File "/usr/local/lib/python3.12/site-packages/airflow/utils/retries.py", line 93, in wrapped_function
    for attempt in run_with_db_retries(max_retries=retries, logger=logger, **retry_kwargs):
                   ^^^^^^^^^^^^^^^^^^^^^^^^^^^^^^^^^^^^^^^^^^^^^^^^^^^^^^^^^^^^^^^^^^^^^^^
  File "/usr/local/lib/python3.12/site-packages/tenacity/__init__.py", line 443, in __iter__
    do = self.iter(retry_state=retry_state)
         ^^^^^^^^^^^^^^^^^^^^^^^^^^^^^^^^^^
  File "/usr/local/lib/python3.12/site-packages/tenacity/__init__.py", line 376, in iter
    result = action(retry_state)
             ^^^^^^^^^^^^^^^^^^^
  File "/usr/local/lib/python3.12/site-packages/tenacity/__init__.py", line 418, in exc_check
    raise retry_exc.reraise()
          ^^^^^^^^^^^^^^^^^^^
  File "/usr/local/lib/python3.12/site-packages/tenacity/__init__.py", line 185, in reraise
    raise self.last_attempt.result()
          ^^^^^^^^^^^^^^^^^^^^^^^^^^
  File "/usr/local/lib/python3.12/concurrent/futures/_base.py", line 449, in result
    return self.__get_result()
           ^^^^^^^^^^^^^^^^^^^
  File "/usr/local/lib/python3.12/concurrent/futures/_base.py", line 401, in __get_result
    raise self._exception
  File "/usr/local/lib/python3.12/site-packages/airflow/utils/retries.py", line 102, in wrapped_function
    return func(*args, **kwargs)
           ^^^^^^^^^^^^^^^^^^^^^
  File "/usr/local/lib/python3.12/site-packages/airflow/jobs/job.py", line 335, in _fetch_from_db
    session.merge(job)
  File "/usr/local/lib/python3.12/site-packages/sqlalchemy/orm/session.py", line 3056, in merge
    return self._merge(
           ^^^^^^^^^^^^
  File "/usr/local/lib/python3.12/site-packages/sqlalchemy/orm/session.py", line 3136, in _merge
    merged = self.get(
             ^^^^^^^^^
  File "/usr/local/lib/python3.12/site-packages/sqlalchemy/orm/session.py", line 2853, in get
    return self._get_impl(
           ^^^^^^^^^^^^^^^
  File "/usr/local/lib/python3.12/site-packages/sqlalchemy/orm/session.py", line 2975, in _get_impl
    return db_load_fn(
           ^^^^^^^^^^^
  File "/usr/local/lib/python3.12/site-packages/sqlalchemy/orm/loading.py", line 530, in load_on_pk_identity
    session.execute(
  File "/usr/local/lib/python3.12/site-packages/sqlalchemy/orm/session.py", line 1716, in execute
    conn = self._connection_for_bind(bind)
           ^^^^^^^^^^^^^^^^^^^^^^^^^^^^^^^
  File "/usr/local/lib/python3.12/site-packages/sqlalchemy/orm/session.py", line 1555, in _connection_for_bind
    return self._transaction._connection_for_bind(
           ^^^^^^^^^^^^^^^^^^^^^^^^^^^^^^^^^^^^^^^
  File "/usr/local/lib/python3.12/site-packages/sqlalchemy/orm/session.py", line 750, in _connection_for_bind
    conn = bind.connect()
           ^^^^^^^^^^^^^^
  File "/usr/local/lib/python3.12/site-packages/sqlalchemy/future/engine.py", line 412, in connect
    return super(Engine, self).connect()
           ^^^^^^^^^^^^^^^^^^^^^^^^^^^^^
  File "/usr/local/lib/python3.12/site-packages/sqlalchemy/engine/base.py", line 3325, in connect
    return self._connection_cls(self, close_with_result=close_with_result)
           ^^^^^^^^^^^^^^^^^^^^^^^^^^^^^^^^^^^^^^^^^^^^^^^^^^^^^^^^^^^^^^^
  File "/usr/local/lib/python3.12/site-packages/sqlalchemy/engine/base.py", line 96, in __init__
    else engine.raw_connection()
         ^^^^^^^^^^^^^^^^^^^^^^^
  File "/usr/local/lib/python3.12/site-packages/sqlalchemy/engine/base.py", line 3404, in raw_connection
    return self._wrap_pool_connect(self.pool.connect, _connection)
           ^^^^^^^^^^^^^^^^^^^^^^^^^^^^^^^^^^^^^^^^^^^^^^^^^^^^^^^
  File "/usr/local/lib/python3.12/site-packages/sqlalchemy/engine/base.py", line 3374, in _wrap_pool_connect
    Connection._handle_dbapi_exception_noconnection(
  File "/usr/local/lib/python3.12/site-packages/sqlalchemy/engine/base.py", line 2208, in _handle_dbapi_exception_noconnection
    util.raise_(
  File "/usr/local/lib/python3.12/site-packages/sqlalchemy/util/compat.py", line 211, in raise_
    raise exception
  File "/usr/local/lib/python3.12/site-packages/sqlalchemy/engine/base.py", line 3371, in _wrap_pool_connect
    return fn()
           ^^^^
  File "/usr/local/lib/python3.12/site-packages/sqlalchemy/pool/base.py", line 327, in connect
    return _ConnectionFairy._checkout(self)
           ^^^^^^^^^^^^^^^^^^^^^^^^^^^^^^^^
  File "/usr/local/lib/python3.12/site-packages/sqlalchemy/pool/base.py", line 894, in _checkout
    fairy = _ConnectionRecord.checkout(pool)
            ^^^^^^^^^^^^^^^^^^^^^^^^^^^^^^^^
  File "/usr/local/lib/python3.12/site-packages/sqlalchemy/pool/base.py", line 493, in checkout
    rec = pool._do_get()
          ^^^^^^^^^^^^^^
  File "/usr/local/lib/python3.12/site-packages/sqlalchemy/pool/impl.py", line 256, in _do_get
    return self._create_connection()
           ^^^^^^^^^^^^^^^^^^^^^^^^^
  File "/usr/local/lib/python3.12/site-packages/sqlalchemy/pool/base.py", line 273, in _create_connection
    return _ConnectionRecord(self)
           ^^^^^^^^^^^^^^^^^^^^^^^
  File "/usr/local/lib/python3.12/site-packages/sqlalchemy/pool/base.py", line 388, in __init__
    self.__connect()
  File "/usr/local/lib/python3.12/site-packages/sqlalchemy/pool/base.py", line 690, in __connect
    with util.safe_reraise():
         ^^^^^^^^^^^^^^^^^^^
  File "/usr/local/lib/python3.12/site-packages/sqlalchemy/util/langhelpers.py", line 70, in __exit__
    compat.raise_(
  File "/usr/local/lib/python3.12/site-packages/sqlalchemy/util/compat.py", line 211, in raise_
    raise exception
  File "/usr/local/lib/python3.12/site-packages/sqlalchemy/pool/base.py", line 686, in __connect
    self.dbapi_connection = connection = pool._invoke_creator(self)
                                         ^^^^^^^^^^^^^^^^^^^^^^^^^^
  File "/usr/local/lib/python3.12/site-packages/sqlalchemy/engine/create.py", line 574, in connect
    return dialect.connect(*cargs, **cparams)
           ^^^^^^^^^^^^^^^^^^^^^^^^^^^^^^^^^^
  File "/usr/local/lib/python3.12/site-packages/sqlalchemy/engine/default.py", line 598, in connect
    return self.dbapi.connect(*cargs, **cparams)
           ^^^^^^^^^^^^^^^^^^^^^^^^^^^^^^^^^^^^^
  File "/usr/local/lib/python3.12/site-packages/psycopg2/__init__.py", line 122, in connect
    conn = _connect(dsn, connection_factory=connection_factory, **kwasync)
           ^^^^^^^^^^^^^^^^^^^^^^^^^^^^^^^^^^^^^^^^^^^^^^^^^^^^^^^^^^^^^^^
sqlalchemy.exc.OperationalError: (psycopg2.OperationalError) could not translate host name "host.docker.internal" to address: Temporary failure in name resolution

(Background on this error at: https://sqlalche.me/e/14/e3q8)
[2024-12-09T09:44:53.147+0000] {job.py:254} ERROR - Job heartbeat failed with error. Scheduler is in unhealthy state
[2024-12-09T09:44:59.217+0000] {job.py:229} INFO - Heartbeat recovered after 39.36 seconds
[2024-12-09T09:45:11.926+0000] {job.py:254} ERROR - Job heartbeat failed with error. Scheduler is in unhealthy state
[2024-12-09T09:45:37.428+0000] {taskinstance.py:3311} ERROR - Task failed with exception
Traceback (most recent call last):
  File "/usr/local/lib/python3.12/site-packages/airflow/models/taskinstance.py", line 767, in _execute_task
    result = _execute_callable(context=context, **execute_callable_kwargs)
             ^^^^^^^^^^^^^^^^^^^^^^^^^^^^^^^^^^^^^^^^^^^^^^^^^^^^^^^^^^^^^
  File "/usr/local/lib/python3.12/site-packages/airflow/models/taskinstance.py", line 733, in _execute_callable
    return ExecutionCallableRunner(
           ^^^^^^^^^^^^^^^^^^^^^^^^
  File "/usr/local/lib/python3.12/site-packages/airflow/utils/operator_helpers.py", line 252, in run
    return self.func(*args, **kwargs)
           ^^^^^^^^^^^^^^^^^^^^^^^^^^
  File "/usr/local/lib/python3.12/site-packages/airflow/models/baseoperator.py", line 417, in wrapper
    return func(self, *args, **kwargs)
           ^^^^^^^^^^^^^^^^^^^^^^^^^^^
  File "/usr/local/lib/python3.12/site-packages/airflow/operators/python.py", line 238, in execute
    return_value = self.execute_callable()
                   ^^^^^^^^^^^^^^^^^^^^^^^
  File "/usr/local/lib/python3.12/site-packages/airflow/operators/python.py", line 256, in execute_callable
    return runner.run(*self.op_args, **self.op_kwargs)
           ^^^^^^^^^^^^^^^^^^^^^^^^^^^^^^^^^^^^^^^^^^^
  File "/usr/local/lib/python3.12/site-packages/airflow/utils/operator_helpers.py", line 252, in run
    return self.func(*args, **kwargs)
           ^^^^^^^^^^^^^^^^^^^^^^^^^^
  File "/opt/Tasks/HistoricalData/company_financial_1.py", line 21, in main_report_1
    login(driver, "https://iboard.ssi.com.vn/analysis/fundamental-analysis", "0373416708", "Lt251208@#$")
  File "/opt/ScrapingPackage/login.py", line 11, in login
    select_option_Xpath(driver, "//button[text()='Đăng nhập']")
  File "/opt/ScrapingPackage/navigation.py", line 17, in select_option_Xpath
    option.click()
  File "/usr/local/lib/python3.12/site-packages/selenium/webdriver/remote/webelement.py", line 93, in click
    self._execute(Command.CLICK_ELEMENT)
  File "/usr/local/lib/python3.12/site-packages/selenium/webdriver/remote/webelement.py", line 394, in _execute
    return self._parent.execute(command, params)
           ^^^^^^^^^^^^^^^^^^^^^^^^^^^^^^^^^^^^^
  File "/usr/local/lib/python3.12/site-packages/selenium/webdriver/remote/webdriver.py", line 344, in execute
    self.error_handler.check_response(response)
  File "/usr/local/lib/python3.12/site-packages/selenium/webdriver/remote/errorhandler.py", line 229, in check_response
    raise exception_class(message, screen, stacktrace)
selenium.common.exceptions.WebDriverException: Message: Unable to execute request for an existing session: java.util.concurrent.TimeoutException
Build info: version: '4.27.0', revision: 'd6e718d'
System info: os.name: 'Linux', os.arch: 'amd64', os.version: '5.15.153.1-microsoft-standard-WSL2', java.version: '17.0.13'
Driver info: driver.version: unknown
Stacktrace:
java.lang.RuntimeException: Unable to execute request for an existing session: java.util.concurrent.TimeoutException
Build info: version: '4.27.0', revision: 'd6e718d'
System info: os.name: 'Linux', os.arch: 'amd64', os.version: '5.15.153.1-microsoft-standard-WSL2', java.version: '17.0.13'
Driver info: driver.version: unknown
	at org.openqa.selenium.grid.router.HandleSession.execute(HandleSession.java:210)
	at org.openqa.selenium.remote.http.Route$PredicatedRoute.handle(Route.java:397)
	at org.openqa.selenium.remote.http.Route.execute(Route.java:69)
	at org.openqa.selenium.remote.http.Route$CombinedRoute.handle(Route.java:360)
	at org.openqa.selenium.remote.http.Route.execute(Route.java:69)
	at org.openqa.selenium.grid.router.Router.execute(Router.java:89)
	at org.openqa.selenium.grid.web.EnsureSpecCompliantResponseHeaders.lambda$apply$0(EnsureSpecCompliantResponseHeaders.java:34)
	at org.openqa.selenium.remote.http.Filter$1.execute(Filter.java:63)
	at org.openqa.selenium.remote.http.Route$CombinedRoute.handle(Route.java:360)
	at org.openqa.selenium.remote.http.Route.execute(Route.java:69)
	at org.openqa.selenium.remote.http.Route$NestedRoute.handle(Route.java:270)
	at org.openqa.selenium.remote.http.Route.execute(Route.java:69)
	at org.openqa.selenium.remote.http.Route$CombinedRoute.handle(Route.java:360)
	at org.openqa.selenium.remote.http.Route.execute(Route.java:69)
	at org.openqa.selenium.remote.AddWebDriverSpecHeaders.lambda$apply$0(AddWebDriverSpecHeaders.java:35)
	at org.openqa.selenium.remote.ErrorFilter.lambda$apply$0(ErrorFilter.java:44)
	at org.openqa.selenium.remote.http.Filter$1.execute(Filter.java:63)
	at org.openqa.selenium.remote.ErrorFilter.lambda$apply$0(ErrorFilter.java:44)
	at org.openqa.selenium.remote.http.Filter$1.execute(Filter.java:63)
	at org.openqa.selenium.netty.server.SeleniumHandler.lambda$channelRead0$0(SeleniumHandler.java:49)
	at java.base/java.util.concurrent.Executors$RunnableAdapter.call(Executors.java:539)
	at java.base/java.util.concurrent.FutureTask.run(FutureTask.java:264)
	at java.base/java.util.concurrent.ThreadPoolExecutor.runWorker(ThreadPoolExecutor.java:1136)
	at java.base/java.util.concurrent.ThreadPoolExecutor$Worker.run(ThreadPoolExecutor.java:635)
	at java.base/java.lang.Thread.run(Thread.java:840)
Caused by: java.util.concurrent.TimeoutException
	at java.base/java.util.concurrent.CompletableFuture$Timeout.run(CompletableFuture.java:2874)
	at java.base/java.util.concurrent.Executors$RunnableAdapter.call(Executors.java:539)
	at java.base/java.util.concurrent.FutureTask.run(FutureTask.java:264)
	at java.base/java.util.concurrent.ScheduledThreadPoolExecutor$ScheduledFutureTask.run(ScheduledThreadPoolExecutor.java:304)
	... 3 more

[2024-12-09T09:45:39.768+0000] {job.py:229} INFO - Heartbeat recovered after 40.57 seconds
[2024-12-09T09:45:39.991+0000] {taskinstance.py:1225} INFO - Marking task as FAILED. dag_id=parallel_historycal_financial_reports, task_id=financial_reports.run_main_report_1, run_id=manual__2024-12-09T09:40:03.368951+00:00, execution_date=20241209T094003, start_date=20241209T094014, end_date=20241209T094539
[2024-12-09T09:45:40.498+0000] {taskinstance.py:340} INFO - ::group::Post task execution logs
[2024-12-09T09:45:40.528+0000] {standard_task_runner.py:124} ERROR - Failed to execute job 196 for task financial_reports.run_main_report_1 (Message: Unable to execute request for an existing session: java.util.concurrent.TimeoutException
Build info: version: '4.27.0', revision: 'd6e718d'
System info: os.name: 'Linux', os.arch: 'amd64', os.version: '5.15.153.1-microsoft-standard-WSL2', java.version: '17.0.13'
Driver info: driver.version: unknown
Stacktrace:
java.lang.RuntimeException: Unable to execute request for an existing session: java.util.concurrent.TimeoutException
Build info: version: '4.27.0', revision: 'd6e718d'
System info: os.name: 'Linux', os.arch: 'amd64', os.version: '5.15.153.1-microsoft-standard-WSL2', java.version: '17.0.13'
Driver info: driver.version: unknown
	at org.openqa.selenium.grid.router.HandleSession.execute(HandleSession.java:210)
	at org.openqa.selenium.remote.http.Route$PredicatedRoute.handle(Route.java:397)
	at org.openqa.selenium.remote.http.Route.execute(Route.java:69)
	at org.openqa.selenium.remote.http.Route$CombinedRoute.handle(Route.java:360)
	at org.openqa.selenium.remote.http.Route.execute(Route.java:69)
	at org.openqa.selenium.grid.router.Router.execute(Router.java:89)
	at org.openqa.selenium.grid.web.EnsureSpecCompliantResponseHeaders.lambda$apply$0(EnsureSpecCompliantResponseHeaders.java:34)
	at org.openqa.selenium.remote.http.Filter$1.execute(Filter.java:63)
	at org.openqa.selenium.remote.http.Route$CombinedRoute.handle(Route.java:360)
	at org.openqa.selenium.remote.http.Route.execute(Route.java:69)
	at org.openqa.selenium.remote.http.Route$NestedRoute.handle(Route.java:270)
	at org.openqa.selenium.remote.http.Route.execute(Route.java:69)
	at org.openqa.selenium.remote.http.Route$CombinedRoute.handle(Route.java:360)
	at org.openqa.selenium.remote.http.Route.execute(Route.java:69)
	at org.openqa.selenium.remote.AddWebDriverSpecHeaders.lambda$apply$0(AddWebDriverSpecHeaders.java:35)
	at org.openqa.selenium.remote.ErrorFilter.lambda$apply$0(ErrorFilter.java:44)
	at org.openqa.selenium.remote.http.Filter$1.execute(Filter.java:63)
	at org.openqa.selenium.remote.ErrorFilter.lambda$apply$0(ErrorFilter.java:44)
	at org.openqa.selenium.remote.http.Filter$1.execute(Filter.java:63)
	at org.openqa.selenium.netty.server.SeleniumHandler.lambda$channelRead0$0(SeleniumHandler.java:49)
	at java.base/java.util.concurrent.Executors$RunnableAdapter.call(Executors.java:539)
	at java.base/java.util.concurrent.FutureTask.run(FutureTask.java:264)
	at java.base/java.util.concurrent.ThreadPoolExecutor.runWorker(ThreadPoolExecutor.java:1136)
	at java.base/java.util.concurrent.ThreadPoolExecutor$Worker.run(ThreadPoolExecutor.java:635)
	at java.base/java.lang.Thread.run(Thread.java:840)
Caused by: java.util.concurrent.TimeoutException
	at java.base/java.util.concurrent.CompletableFuture$Timeout.run(CompletableFuture.java:2874)
	at java.base/java.util.concurrent.Executors$RunnableAdapter.call(Executors.java:539)
	at java.base/java.util.concurrent.FutureTask.run(FutureTask.java:264)
	at java.base/java.util.concurrent.ScheduledThreadPoolExecutor$ScheduledFutureTask.run(ScheduledThreadPoolExecutor.java:304)
	... 3 more
; 5983)
Traceback (most recent call last):
  File "/usr/local/lib/python3.12/site-packages/airflow/task/task_runner/standard_task_runner.py", line 117, in _start_by_fork
    ret = args.func(args, dag=self.dag)
          ^^^^^^^^^^^^^^^^^^^^^^^^^^^^^
  File "/usr/local/lib/python3.12/site-packages/airflow/cli/cli_config.py", line 49, in command
    return func(*args, **kwargs)
           ^^^^^^^^^^^^^^^^^^^^^
  File "/usr/local/lib/python3.12/site-packages/airflow/utils/cli.py", line 116, in wrapper
    return f(*args, **kwargs)
           ^^^^^^^^^^^^^^^^^^
  File "/usr/local/lib/python3.12/site-packages/airflow/cli/commands/task_command.py", line 483, in task_run
    task_return_code = _run_task_by_selected_method(args, _dag, ti)
                       ^^^^^^^^^^^^^^^^^^^^^^^^^^^^^^^^^^^^^^^^^^^^
  File "/usr/local/lib/python3.12/site-packages/airflow/cli/commands/task_command.py", line 256, in _run_task_by_selected_method
    return _run_raw_task(args, ti)
           ^^^^^^^^^^^^^^^^^^^^^^^
  File "/usr/local/lib/python3.12/site-packages/airflow/cli/commands/task_command.py", line 341, in _run_raw_task
    return ti._run_raw_task(
           ^^^^^^^^^^^^^^^^^
  File "/usr/local/lib/python3.12/site-packages/airflow/utils/session.py", line 97, in wrapper
    return func(*args, session=session, **kwargs)
           ^^^^^^^^^^^^^^^^^^^^^^^^^^^^^^^^^^^^^^
  File "/usr/local/lib/python3.12/site-packages/airflow/models/taskinstance.py", line 3005, in _run_raw_task
    return _run_raw_task(
           ^^^^^^^^^^^^^^
  File "/usr/local/lib/python3.12/site-packages/airflow/models/taskinstance.py", line 273, in _run_raw_task
    TaskInstance._execute_task_with_callbacks(
  File "/usr/local/lib/python3.12/site-packages/airflow/models/taskinstance.py", line 3159, in _execute_task_with_callbacks
    result = self._execute_task(context, task_orig)
             ^^^^^^^^^^^^^^^^^^^^^^^^^^^^^^^^^^^^^^
  File "/usr/local/lib/python3.12/site-packages/airflow/models/taskinstance.py", line 3183, in _execute_task
    return _execute_task(self, context, task_orig)
           ^^^^^^^^^^^^^^^^^^^^^^^^^^^^^^^^^^^^^^^
  File "/usr/local/lib/python3.12/site-packages/airflow/models/taskinstance.py", line 767, in _execute_task
    result = _execute_callable(context=context, **execute_callable_kwargs)
             ^^^^^^^^^^^^^^^^^^^^^^^^^^^^^^^^^^^^^^^^^^^^^^^^^^^^^^^^^^^^^
  File "/usr/local/lib/python3.12/site-packages/airflow/models/taskinstance.py", line 733, in _execute_callable
    return ExecutionCallableRunner(
           ^^^^^^^^^^^^^^^^^^^^^^^^
  File "/usr/local/lib/python3.12/site-packages/airflow/utils/operator_helpers.py", line 252, in run
    return self.func(*args, **kwargs)
           ^^^^^^^^^^^^^^^^^^^^^^^^^^
  File "/usr/local/lib/python3.12/site-packages/airflow/models/baseoperator.py", line 417, in wrapper
    return func(self, *args, **kwargs)
           ^^^^^^^^^^^^^^^^^^^^^^^^^^^
  File "/usr/local/lib/python3.12/site-packages/airflow/operators/python.py", line 238, in execute
    return_value = self.execute_callable()
                   ^^^^^^^^^^^^^^^^^^^^^^^
  File "/usr/local/lib/python3.12/site-packages/airflow/operators/python.py", line 256, in execute_callable
    return runner.run(*self.op_args, **self.op_kwargs)
           ^^^^^^^^^^^^^^^^^^^^^^^^^^^^^^^^^^^^^^^^^^^
  File "/usr/local/lib/python3.12/site-packages/airflow/utils/operator_helpers.py", line 252, in run
    return self.func(*args, **kwargs)
           ^^^^^^^^^^^^^^^^^^^^^^^^^^
  File "/opt/Tasks/HistoricalData/company_financial_1.py", line 21, in main_report_1
    login(driver, "https://iboard.ssi.com.vn/analysis/fundamental-analysis", "0373416708", "Lt251208@#$")
  File "/opt/ScrapingPackage/login.py", line 11, in login
    select_option_Xpath(driver, "//button[text()='Đăng nhập']")
  File "/opt/ScrapingPackage/navigation.py", line 17, in select_option_Xpath
    option.click()
  File "/usr/local/lib/python3.12/site-packages/selenium/webdriver/remote/webelement.py", line 93, in click
    self._execute(Command.CLICK_ELEMENT)
  File "/usr/local/lib/python3.12/site-packages/selenium/webdriver/remote/webelement.py", line 394, in _execute
    return self._parent.execute(command, params)
           ^^^^^^^^^^^^^^^^^^^^^^^^^^^^^^^^^^^^^
  File "/usr/local/lib/python3.12/site-packages/selenium/webdriver/remote/webdriver.py", line 344, in execute
    self.error_handler.check_response(response)
  File "/usr/local/lib/python3.12/site-packages/selenium/webdriver/remote/errorhandler.py", line 229, in check_response
    raise exception_class(message, screen, stacktrace)
selenium.common.exceptions.WebDriverException: Message: Unable to execute request for an existing session: java.util.concurrent.TimeoutException
Build info: version: '4.27.0', revision: 'd6e718d'
System info: os.name: 'Linux', os.arch: 'amd64', os.version: '5.15.153.1-microsoft-standard-WSL2', java.version: '17.0.13'
Driver info: driver.version: unknown
Stacktrace:
java.lang.RuntimeException: Unable to execute request for an existing session: java.util.concurrent.TimeoutException
Build info: version: '4.27.0', revision: 'd6e718d'
System info: os.name: 'Linux', os.arch: 'amd64', os.version: '5.15.153.1-microsoft-standard-WSL2', java.version: '17.0.13'
Driver info: driver.version: unknown
	at org.openqa.selenium.grid.router.HandleSession.execute(HandleSession.java:210)
	at org.openqa.selenium.remote.http.Route$PredicatedRoute.handle(Route.java:397)
	at org.openqa.selenium.remote.http.Route.execute(Route.java:69)
	at org.openqa.selenium.remote.http.Route$CombinedRoute.handle(Route.java:360)
	at org.openqa.selenium.remote.http.Route.execute(Route.java:69)
	at org.openqa.selenium.grid.router.Router.execute(Router.java:89)
	at org.openqa.selenium.grid.web.EnsureSpecCompliantResponseHeaders.lambda$apply$0(EnsureSpecCompliantResponseHeaders.java:34)
	at org.openqa.selenium.remote.http.Filter$1.execute(Filter.java:63)
	at org.openqa.selenium.remote.http.Route$CombinedRoute.handle(Route.java:360)
	at org.openqa.selenium.remote.http.Route.execute(Route.java:69)
	at org.openqa.selenium.remote.http.Route$NestedRoute.handle(Route.java:270)
	at org.openqa.selenium.remote.http.Route.execute(Route.java:69)
	at org.openqa.selenium.remote.http.Route$CombinedRoute.handle(Route.java:360)
	at org.openqa.selenium.remote.http.Route.execute(Route.java:69)
	at org.openqa.selenium.remote.AddWebDriverSpecHeaders.lambda$apply$0(AddWebDriverSpecHeaders.java:35)
	at org.openqa.selenium.remote.ErrorFilter.lambda$apply$0(ErrorFilter.java:44)
	at org.openqa.selenium.remote.http.Filter$1.execute(Filter.java:63)
	at org.openqa.selenium.remote.ErrorFilter.lambda$apply$0(ErrorFilter.java:44)
	at org.openqa.selenium.remote.http.Filter$1.execute(Filter.java:63)
	at org.openqa.selenium.netty.server.SeleniumHandler.lambda$channelRead0$0(SeleniumHandler.java:49)
	at java.base/java.util.concurrent.Executors$RunnableAdapter.call(Executors.java:539)
	at java.base/java.util.concurrent.FutureTask.run(FutureTask.java:264)
	at java.base/java.util.concurrent.ThreadPoolExecutor.runWorker(ThreadPoolExecutor.java:1136)
	at java.base/java.util.concurrent.ThreadPoolExecutor$Worker.run(ThreadPoolExecutor.java:635)
	at java.base/java.lang.Thread.run(Thread.java:840)
Caused by: java.util.concurrent.TimeoutException
	at java.base/java.util.concurrent.CompletableFuture$Timeout.run(CompletableFuture.java:2874)
	at java.base/java.util.concurrent.Executors$RunnableAdapter.call(Executors.java:539)
	at java.base/java.util.concurrent.FutureTask.run(FutureTask.java:264)
	at java.base/java.util.concurrent.ScheduledThreadPoolExecutor$ScheduledFutureTask.run(ScheduledThreadPoolExecutor.java:304)
	... 3 more

[2024-12-09T09:45:42.344+0000] {local_task_job_runner.py:266} INFO - Task exited with return code 1
[2024-12-09T09:45:44.732+0000] {taskinstance.py:3895} INFO - 0 downstream tasks scheduled from follow-on schedule check
[2024-12-09T09:45:44.791+0000] {local_task_job_runner.py:245} INFO - ::endgroup::
[2024-12-09T09:45:44.849+0000] {standard_task_runner.py:217} INFO - Process not found (most likely exited), stop collecting metrics
