[2024-12-07T09:40:35.762+0000] {local_task_job_runner.py:123} INFO - ::group::Pre task execution logs
[2024-12-07T09:40:35.804+0000] {taskinstance.py:2613} INFO - Dependencies all met for dep_context=non-requeueable deps ti=<TaskInstance: parallel_financial_reports.financial_reports.run_main_report manual__2024-12-07T09:40:29.896649+00:00 [queued]>
[2024-12-07T09:40:35.823+0000] {taskinstance.py:2613} INFO - Dependencies all met for dep_context=requeueable deps ti=<TaskInstance: parallel_financial_reports.financial_reports.run_main_report manual__2024-12-07T09:40:29.896649+00:00 [queued]>
[2024-12-07T09:40:35.824+0000] {taskinstance.py:2866} INFO - Starting attempt 1 of 1
[2024-12-07T09:40:35.852+0000] {taskinstance.py:2889} INFO - Executing <Task(PythonOperator): financial_reports.run_main_report> on 2024-12-07 09:40:29.896649+00:00
[2024-12-07T09:40:35.866+0000] {logging_mixin.py:190} WARNING - /usr/local/lib/python3.12/site-packages/airflow/task/task_runner/standard_task_runner.py:70 DeprecationWarning: This process (pid=1053) is multi-threaded, use of fork() may lead to deadlocks in the child.
[2024-12-07T09:40:35.869+0000] {standard_task_runner.py:72} INFO - Started process 1056 to run task
[2024-12-07T09:40:35.866+0000] {standard_task_runner.py:104} INFO - Running: ['airflow', 'tasks', 'run', 'parallel_financial_reports', 'financial_reports.run_main_report', 'manual__2024-12-07T09:40:29.896649+00:00', '--job-id', '41', '--raw', '--subdir', 'DAGS_FOLDER/Extract_history_data.py', '--cfg-path', '/tmp/tmpbi623oxa']
[2024-12-07T09:40:35.870+0000] {standard_task_runner.py:105} INFO - Job 41: Subtask financial_reports.run_main_report
[2024-12-07T09:40:36.019+0000] {task_command.py:467} INFO - Running <TaskInstance: parallel_financial_reports.financial_reports.run_main_report manual__2024-12-07T09:40:29.896649+00:00 [running]> on host dc7f1c1b5340
[2024-12-07T09:40:36.212+0000] {taskinstance.py:3132} INFO - Exporting env vars: AIRFLOW_CTX_DAG_OWNER='airflowDWH' AIRFLOW_CTX_DAG_ID='parallel_financial_reports' AIRFLOW_CTX_TASK_ID='financial_reports.run_main_report' AIRFLOW_CTX_EXECUTION_DATE='2024-12-07T09:40:29.896649+00:00' AIRFLOW_CTX_TRY_NUMBER='1' AIRFLOW_CTX_DAG_RUN_ID='manual__2024-12-07T09:40:29.896649+00:00'
[2024-12-07T09:40:36.214+0000] {taskinstance.py:731} INFO - ::endgroup::
[2024-12-07T09:41:38.357+0000] {logging_mixin.py:190} INFO - Dữ liệu Cân Đối Kế Toán cho mã AGG thiếu từ các năm: 2017.
[2024-12-07T09:42:10.703+0000] {logging_mixin.py:190} INFO - Dữ liệu Kết Quả Kinh Doanh cho mã AGG thiếu từ các năm: 2017.
[2024-12-07T09:42:21.732+0000] {logging_mixin.py:190} INFO - Dữ liệu Lưu Chuyển Tiền Tệ cho mã AGG thiếu từ các năm: 2017.
[2024-12-07T09:42:21.733+0000] {logging_mixin.py:190} INFO - Mã AGG đã được xử lý
[2024-12-07T09:42:50.832+0000] {logging_mixin.py:190} INFO - Dữ liệu Cân Đối Kế Toán cho mã LEC thiếu từ các năm: 2017.
[2024-12-07T09:43:49.582+0000] {logging_mixin.py:190} INFO - Mã LEC đã được xử lý
[2024-12-07T09:44:20.841+0000] {logging_mixin.py:190} INFO - Dữ liệu Cân Đối Kế Toán cho mã BIG thiếu từ các năm: 2017.
[2024-12-07T09:44:22.362+0000] {logging_mixin.py:190} INFO - Dữ liệu Kết Quả Kinh Doanh cho mã BIG thiếu từ các năm: 2024.
[2024-12-07T09:44:23.276+0000] {logging_mixin.py:190} INFO - Dữ liệu Lưu Chuyển Tiền Tệ cho mã BIG thiếu từ các năm: 2024.
[2024-12-07T09:44:23.280+0000] {logging_mixin.py:190} INFO - Mã BIG đã được xử lý
[2024-12-07T09:44:53.732+0000] {logging_mixin.py:190} INFO - Dữ liệu Cân Đối Kế Toán cho mã FDC thiếu từ các năm: 2017.
[2024-12-07T09:44:54.552+0000] {logging_mixin.py:190} INFO - Dữ liệu Kết Quả Kinh Doanh cho mã FDC thiếu từ các năm: 2024.
[2024-12-07T09:45:13.937+0000] {logging_mixin.py:190} INFO - Mã FDC đã được xử lý
[2024-12-07T09:45:43.580+0000] {logging_mixin.py:190} INFO - Dữ liệu Cân Đối Kế Toán cho mã API thiếu từ các năm: 2017.
[2024-12-07T09:46:44.748+0000] {logging_mixin.py:190} INFO - Mã API đã được xử lý
[2024-12-07T09:46:44.880+0000] {logging_mixin.py:190} INFO - Đã lưu dữ liệu sau 5 mã chứng khoán.
[2024-12-07T09:47:12.933+0000] {logging_mixin.py:190} INFO - Dữ liệu Cân Đối Kế Toán cho mã D11 thiếu từ các năm: 2017.
[2024-12-07T09:48:11.747+0000] {logging_mixin.py:190} INFO - Mã D11 đã được xử lý
[2024-12-07T09:48:37.144+0000] {logging_mixin.py:190} INFO - Dữ liệu Cân Đối Kế Toán cho mã HAR thiếu từ các năm: 2017.
[2024-12-07T09:49:33.177+0000] {logging_mixin.py:190} INFO - Mã HAR đã được xử lý
[2024-12-07T09:49:58.720+0000] {logging_mixin.py:190} INFO - Dữ liệu Cân Đối Kế Toán cho mã XDH thiếu từ các năm: 2017.
[2024-12-07T09:50:11.372+0000] {logging_mixin.py:190} INFO - Dữ liệu Kết Quả Kinh Doanh cho mã XDH thiếu từ các năm: 2020.
[2024-12-07T09:50:16.194+0000] {logging_mixin.py:190} INFO - Dữ liệu Lưu Chuyển Tiền Tệ cho mã XDH thiếu từ các năm: 2020.
[2024-12-07T09:50:16.197+0000] {logging_mixin.py:190} INFO - Mã XDH đã được xử lý
[2024-12-07T09:50:42.392+0000] {logging_mixin.py:190} INFO - Dữ liệu Cân Đối Kế Toán cho mã C21 thiếu từ các năm: 2017.
[2024-12-07T09:50:57.650+0000] {logging_mixin.py:190} INFO - Lỗi khi crawl dữ liệu 'Kết Quả Kinh Doanh' cho mã C21: 13 columns passed, passed data had 16 columns
[2024-12-07T09:51:13.984+0000] {logging_mixin.py:190} INFO - Mã C21 đã được xử lý
[2024-12-07T09:51:40.594+0000] {logging_mixin.py:190} INFO - Dữ liệu Cân Đối Kế Toán cho mã D2D thiếu từ các năm: 2017.
[2024-12-07T09:52:44.411+0000] {logging_mixin.py:190} INFO - Mã D2D đã được xử lý
[2024-12-07T09:52:44.503+0000] {logging_mixin.py:190} INFO - Đã lưu dữ liệu sau 10 mã chứng khoán.
[2024-12-07T09:53:14.095+0000] {logging_mixin.py:190} INFO - Dữ liệu Cân Đối Kế Toán cho mã CK8 thiếu từ các năm: 2017.
[2024-12-07T09:53:15.583+0000] {logging_mixin.py:190} INFO - Dữ liệu Kết Quả Kinh Doanh cho mã CK8 thiếu từ các năm: 2024.
[2024-12-07T09:53:16.738+0000] {logging_mixin.py:190} INFO - Dữ liệu Lưu Chuyển Tiền Tệ cho mã CK8 thiếu từ các năm: 2024.
[2024-12-07T09:53:16.742+0000] {logging_mixin.py:190} INFO - Mã CK8 đã được xử lý
[2024-12-07T09:53:43.187+0000] {logging_mixin.py:190} INFO - Dữ liệu Cân Đối Kế Toán cho mã AAV thiếu từ các năm: 2017.
[2024-12-07T09:53:43.922+0000] {logging_mixin.py:190} INFO - Dữ liệu Kết Quả Kinh Doanh cho mã AAV thiếu từ các năm: 2024.
[2024-12-07T09:53:57.105+0000] {logging_mixin.py:190} INFO - Mã AAV đã được xử lý
[2024-12-07T09:54:31.414+0000] {logging_mixin.py:190} INFO - Dữ liệu Cân Đối Kế Toán cho mã CLG thiếu từ các năm: 2017.
[2024-12-07T09:55:55.507+0000] {logging_mixin.py:190} INFO - Mã CLG đã được xử lý
[2024-12-07T09:56:18.140+0000] {job.py:229} INFO - Heartbeat recovered after 29.11 seconds
[2024-12-07T09:56:53.429+0000] {logging_mixin.py:190} INFO - Dữ liệu Cân Đối Kế Toán cho mã MGR thiếu từ các năm: 2017.
[2024-12-07T09:57:08.243+0000] {logging_mixin.py:190} INFO - Dữ liệu Kết Quả Kinh Doanh cho mã MGR thiếu từ các năm: 2020.
[2024-12-07T09:57:13.315+0000] {logging_mixin.py:190} INFO - Dữ liệu Lưu Chuyển Tiền Tệ cho mã MGR thiếu từ các năm: 2020.
[2024-12-07T09:57:13.317+0000] {logging_mixin.py:190} INFO - Mã MGR đã được xử lý
[2024-12-07T09:57:41.931+0000] {logging_mixin.py:190} INFO - Dữ liệu Cân Đối Kế Toán cho mã HPI thiếu từ các năm: 2017.
[2024-12-07T09:58:28.915+0000] {job.py:239} ERROR - Job heartbeat failed with error
Traceback (most recent call last):
  File "/usr/local/lib/python3.12/site-packages/sqlalchemy/engine/base.py", line 3371, in _wrap_pool_connect
    return fn()
           ^^^^
  File "/usr/local/lib/python3.12/site-packages/sqlalchemy/pool/base.py", line 327, in connect
    return _ConnectionFairy._checkout(self)
           ^^^^^^^^^^^^^^^^^^^^^^^^^^^^^^^^
  File "/usr/local/lib/python3.12/site-packages/sqlalchemy/pool/base.py", line 894, in _checkout
    fairy = _ConnectionRecord.checkout(pool)
            ^^^^^^^^^^^^^^^^^^^^^^^^^^^^^^^^
  File "/usr/local/lib/python3.12/site-packages/sqlalchemy/pool/base.py", line 493, in checkout
    rec = pool._do_get()
          ^^^^^^^^^^^^^^
  File "/usr/local/lib/python3.12/site-packages/sqlalchemy/pool/impl.py", line 256, in _do_get
    return self._create_connection()
           ^^^^^^^^^^^^^^^^^^^^^^^^^
  File "/usr/local/lib/python3.12/site-packages/sqlalchemy/pool/base.py", line 273, in _create_connection
    return _ConnectionRecord(self)
           ^^^^^^^^^^^^^^^^^^^^^^^
  File "/usr/local/lib/python3.12/site-packages/sqlalchemy/pool/base.py", line 388, in __init__
    self.__connect()
  File "/usr/local/lib/python3.12/site-packages/sqlalchemy/pool/base.py", line 690, in __connect
    with util.safe_reraise():
         ^^^^^^^^^^^^^^^^^^^
  File "/usr/local/lib/python3.12/site-packages/sqlalchemy/util/langhelpers.py", line 70, in __exit__
    compat.raise_(
  File "/usr/local/lib/python3.12/site-packages/sqlalchemy/util/compat.py", line 211, in raise_
    raise exception
  File "/usr/local/lib/python3.12/site-packages/sqlalchemy/pool/base.py", line 686, in __connect
    self.dbapi_connection = connection = pool._invoke_creator(self)
                                         ^^^^^^^^^^^^^^^^^^^^^^^^^^
  File "/usr/local/lib/python3.12/site-packages/sqlalchemy/engine/create.py", line 574, in connect
    return dialect.connect(*cargs, **cparams)
           ^^^^^^^^^^^^^^^^^^^^^^^^^^^^^^^^^^
  File "/usr/local/lib/python3.12/site-packages/sqlalchemy/engine/default.py", line 598, in connect
    return self.dbapi.connect(*cargs, **cparams)
           ^^^^^^^^^^^^^^^^^^^^^^^^^^^^^^^^^^^^^
  File "/usr/local/lib/python3.12/site-packages/psycopg2/__init__.py", line 122, in connect
    conn = _connect(dsn, connection_factory=connection_factory, **kwasync)
           ^^^^^^^^^^^^^^^^^^^^^^^^^^^^^^^^^^^^^^^^^^^^^^^^^^^^^^^^^^^^^^^
psycopg2.OperationalError: could not translate host name "host.docker.internal" to address: Temporary failure in name resolution


The above exception was the direct cause of the following exception:

Traceback (most recent call last):
  File "/usr/local/lib/python3.12/site-packages/airflow/jobs/job.py", line 207, in heartbeat
    self._merge_from(Job._fetch_from_db(self, session))
                     ^^^^^^^^^^^^^^^^^^^^^^^^^^^^^^^^^
  File "/usr/local/lib/python3.12/site-packages/airflow/api_internal/internal_api_call.py", line 166, in wrapper
    return func(*args, **kwargs)
           ^^^^^^^^^^^^^^^^^^^^^
  File "/usr/local/lib/python3.12/site-packages/airflow/utils/session.py", line 94, in wrapper
    return func(*args, **kwargs)
           ^^^^^^^^^^^^^^^^^^^^^
  File "/usr/local/lib/python3.12/site-packages/airflow/utils/retries.py", line 93, in wrapped_function
    for attempt in run_with_db_retries(max_retries=retries, logger=logger, **retry_kwargs):
                   ^^^^^^^^^^^^^^^^^^^^^^^^^^^^^^^^^^^^^^^^^^^^^^^^^^^^^^^^^^^^^^^^^^^^^^^
  File "/usr/local/lib/python3.12/site-packages/tenacity/__init__.py", line 443, in __iter__
    do = self.iter(retry_state=retry_state)
         ^^^^^^^^^^^^^^^^^^^^^^^^^^^^^^^^^^
  File "/usr/local/lib/python3.12/site-packages/tenacity/__init__.py", line 376, in iter
    result = action(retry_state)
             ^^^^^^^^^^^^^^^^^^^
  File "/usr/local/lib/python3.12/site-packages/tenacity/__init__.py", line 418, in exc_check
    raise retry_exc.reraise()
          ^^^^^^^^^^^^^^^^^^^
  File "/usr/local/lib/python3.12/site-packages/tenacity/__init__.py", line 185, in reraise
    raise self.last_attempt.result()
          ^^^^^^^^^^^^^^^^^^^^^^^^^^
  File "/usr/local/lib/python3.12/concurrent/futures/_base.py", line 449, in result
    return self.__get_result()
           ^^^^^^^^^^^^^^^^^^^
  File "/usr/local/lib/python3.12/concurrent/futures/_base.py", line 401, in __get_result
    raise self._exception
  File "/usr/local/lib/python3.12/site-packages/airflow/utils/retries.py", line 102, in wrapped_function
    return func(*args, **kwargs)
           ^^^^^^^^^^^^^^^^^^^^^
  File "/usr/local/lib/python3.12/site-packages/airflow/jobs/job.py", line 335, in _fetch_from_db
    session.merge(job)
  File "/usr/local/lib/python3.12/site-packages/sqlalchemy/orm/session.py", line 3056, in merge
    return self._merge(
           ^^^^^^^^^^^^
  File "/usr/local/lib/python3.12/site-packages/sqlalchemy/orm/session.py", line 3136, in _merge
    merged = self.get(
             ^^^^^^^^^
  File "/usr/local/lib/python3.12/site-packages/sqlalchemy/orm/session.py", line 2853, in get
    return self._get_impl(
           ^^^^^^^^^^^^^^^
  File "/usr/local/lib/python3.12/site-packages/sqlalchemy/orm/session.py", line 2975, in _get_impl
    return db_load_fn(
           ^^^^^^^^^^^
  File "/usr/local/lib/python3.12/site-packages/sqlalchemy/orm/loading.py", line 530, in load_on_pk_identity
    session.execute(
  File "/usr/local/lib/python3.12/site-packages/sqlalchemy/orm/session.py", line 1716, in execute
    conn = self._connection_for_bind(bind)
           ^^^^^^^^^^^^^^^^^^^^^^^^^^^^^^^
  File "/usr/local/lib/python3.12/site-packages/sqlalchemy/orm/session.py", line 1555, in _connection_for_bind
    return self._transaction._connection_for_bind(
           ^^^^^^^^^^^^^^^^^^^^^^^^^^^^^^^^^^^^^^^
  File "/usr/local/lib/python3.12/site-packages/sqlalchemy/orm/session.py", line 750, in _connection_for_bind
    conn = bind.connect()
           ^^^^^^^^^^^^^^
  File "/usr/local/lib/python3.12/site-packages/sqlalchemy/future/engine.py", line 412, in connect
    return super(Engine, self).connect()
           ^^^^^^^^^^^^^^^^^^^^^^^^^^^^^
  File "/usr/local/lib/python3.12/site-packages/sqlalchemy/engine/base.py", line 3325, in connect
    return self._connection_cls(self, close_with_result=close_with_result)
           ^^^^^^^^^^^^^^^^^^^^^^^^^^^^^^^^^^^^^^^^^^^^^^^^^^^^^^^^^^^^^^^
  File "/usr/local/lib/python3.12/site-packages/sqlalchemy/engine/base.py", line 96, in __init__
    else engine.raw_connection()
         ^^^^^^^^^^^^^^^^^^^^^^^
  File "/usr/local/lib/python3.12/site-packages/sqlalchemy/engine/base.py", line 3404, in raw_connection
    return self._wrap_pool_connect(self.pool.connect, _connection)
           ^^^^^^^^^^^^^^^^^^^^^^^^^^^^^^^^^^^^^^^^^^^^^^^^^^^^^^^
  File "/usr/local/lib/python3.12/site-packages/sqlalchemy/engine/base.py", line 3374, in _wrap_pool_connect
    Connection._handle_dbapi_exception_noconnection(
  File "/usr/local/lib/python3.12/site-packages/sqlalchemy/engine/base.py", line 2208, in _handle_dbapi_exception_noconnection
    util.raise_(
  File "/usr/local/lib/python3.12/site-packages/sqlalchemy/util/compat.py", line 211, in raise_
    raise exception
  File "/usr/local/lib/python3.12/site-packages/sqlalchemy/engine/base.py", line 3371, in _wrap_pool_connect
    return fn()
           ^^^^
  File "/usr/local/lib/python3.12/site-packages/sqlalchemy/pool/base.py", line 327, in connect
    return _ConnectionFairy._checkout(self)
           ^^^^^^^^^^^^^^^^^^^^^^^^^^^^^^^^
  File "/usr/local/lib/python3.12/site-packages/sqlalchemy/pool/base.py", line 894, in _checkout
    fairy = _ConnectionRecord.checkout(pool)
            ^^^^^^^^^^^^^^^^^^^^^^^^^^^^^^^^
  File "/usr/local/lib/python3.12/site-packages/sqlalchemy/pool/base.py", line 493, in checkout
    rec = pool._do_get()
          ^^^^^^^^^^^^^^
  File "/usr/local/lib/python3.12/site-packages/sqlalchemy/pool/impl.py", line 256, in _do_get
    return self._create_connection()
           ^^^^^^^^^^^^^^^^^^^^^^^^^
  File "/usr/local/lib/python3.12/site-packages/sqlalchemy/pool/base.py", line 273, in _create_connection
    return _ConnectionRecord(self)
           ^^^^^^^^^^^^^^^^^^^^^^^
  File "/usr/local/lib/python3.12/site-packages/sqlalchemy/pool/base.py", line 388, in __init__
    self.__connect()
  File "/usr/local/lib/python3.12/site-packages/sqlalchemy/pool/base.py", line 690, in __connect
    with util.safe_reraise():
         ^^^^^^^^^^^^^^^^^^^
  File "/usr/local/lib/python3.12/site-packages/sqlalchemy/util/langhelpers.py", line 70, in __exit__
    compat.raise_(
  File "/usr/local/lib/python3.12/site-packages/sqlalchemy/util/compat.py", line 211, in raise_
    raise exception
  File "/usr/local/lib/python3.12/site-packages/sqlalchemy/pool/base.py", line 686, in __connect
    self.dbapi_connection = connection = pool._invoke_creator(self)
                                         ^^^^^^^^^^^^^^^^^^^^^^^^^^
  File "/usr/local/lib/python3.12/site-packages/sqlalchemy/engine/create.py", line 574, in connect
    return dialect.connect(*cargs, **cparams)
           ^^^^^^^^^^^^^^^^^^^^^^^^^^^^^^^^^^
  File "/usr/local/lib/python3.12/site-packages/sqlalchemy/engine/default.py", line 598, in connect
    return self.dbapi.connect(*cargs, **cparams)
           ^^^^^^^^^^^^^^^^^^^^^^^^^^^^^^^^^^^^^
  File "/usr/local/lib/python3.12/site-packages/psycopg2/__init__.py", line 122, in connect
    conn = _connect(dsn, connection_factory=connection_factory, **kwasync)
           ^^^^^^^^^^^^^^^^^^^^^^^^^^^^^^^^^^^^^^^^^^^^^^^^^^^^^^^^^^^^^^^
sqlalchemy.exc.OperationalError: (psycopg2.OperationalError) could not translate host name "host.docker.internal" to address: Temporary failure in name resolution

(Background on this error at: https://sqlalche.me/e/14/e3q8)
[2024-12-07T09:58:29.082+0000] {job.py:254} ERROR - Job heartbeat failed with error. Scheduler is in unhealthy state
[2024-12-07T09:58:38.817+0000] {job.py:229} INFO - Heartbeat recovered after 45.77 seconds
[2024-12-07T09:59:21.119+0000] {logging_mixin.py:190} INFO - Mã HPI đã được xử lý
[2024-12-07T09:59:21.180+0000] {logging_mixin.py:190} INFO - Đã lưu dữ liệu sau 15 mã chứng khoán.
[2024-12-07T09:59:50.346+0000] {logging_mixin.py:190} INFO - Dữ liệu Cân Đối Kế Toán cho mã DRH thiếu từ các năm: 2017.
[2024-12-07T09:59:53.784+0000] {local_task_job_runner.py:346} WARNING - State of this instance has been externally set to failed. Terminating instance.
[2024-12-07T09:59:53.786+0000] {local_task_job_runner.py:245} INFO - ::endgroup::
[2024-12-07T09:59:53.794+0000] {process_utils.py:132} INFO - Sending 15 to group 1056. PIDs of all processes in the group: [1056]
[2024-12-07T09:59:53.797+0000] {process_utils.py:87} INFO - Sending the signal 15 to group 1056
[2024-12-07T09:59:53.800+0000] {taskinstance.py:3093} ERROR - Received SIGTERM. Terminating subprocesses.
[2024-12-07T09:59:54.047+0000] {taskinstance.py:340} INFO - ::group::Post task execution logs
[2024-12-07T09:59:54.131+0000] {process_utils.py:80} INFO - Process psutil.Process(pid=1056, status='terminated', exitcode=0, started='09:40:34') (1056) terminated with exit code 0
