[2024-12-09T10:07:14.512+0000] {local_task_job_runner.py:123} INFO - ::group::Pre task execution logs
[2024-12-09T10:07:14.857+0000] {taskinstance.py:2613} INFO - Dependencies all met for dep_context=non-requeueable deps ti=<TaskInstance: parallel_historycal_financial_reports.financial_reports.run_main_report_1 manual__2024-12-09T10:07:06.230150+00:00 [queued]>
[2024-12-09T10:07:14.926+0000] {taskinstance.py:2613} INFO - Dependencies all met for dep_context=requeueable deps ti=<TaskInstance: parallel_historycal_financial_reports.financial_reports.run_main_report_1 manual__2024-12-09T10:07:06.230150+00:00 [queued]>
[2024-12-09T10:07:14.927+0000] {taskinstance.py:2866} INFO - Starting attempt 1 of 1
[2024-12-09T10:07:14.965+0000] {taskinstance.py:2889} INFO - Executing <Task(PythonOperator): financial_reports.run_main_report_1> on 2024-12-09 10:07:06.230150+00:00
[2024-12-09T10:07:14.982+0000] {logging_mixin.py:190} WARNING - /usr/local/lib/python3.12/site-packages/airflow/task/task_runner/standard_task_runner.py:70 DeprecationWarning: This process (pid=613) is multi-threaded, use of fork() may lead to deadlocks in the child.
[2024-12-09T10:07:14.983+0000] {standard_task_runner.py:72} INFO - Started process 619 to run task
[2024-12-09T10:07:14.985+0000] {standard_task_runner.py:104} INFO - Running: ['airflow', 'tasks', 'run', 'parallel_historycal_financial_reports', 'financial_reports.run_main_report_1', 'manual__2024-12-09T10:07:06.230150+00:00', '--job-id', '203', '--raw', '--subdir', 'DAGS_FOLDER/Extract_history_financial_data.py', '--cfg-path', '/tmp/tmp4v0mem8t']
[2024-12-09T10:07:14.989+0000] {standard_task_runner.py:105} INFO - Job 203: Subtask financial_reports.run_main_report_1
[2024-12-09T10:07:15.277+0000] {task_command.py:467} INFO - Running <TaskInstance: parallel_historycal_financial_reports.financial_reports.run_main_report_1 manual__2024-12-09T10:07:06.230150+00:00 [running]> on host 1ce88e57b286
[2024-12-09T10:07:15.592+0000] {taskinstance.py:3132} INFO - Exporting env vars: AIRFLOW_CTX_DAG_OWNER='airflowDWH' AIRFLOW_CTX_DAG_ID='parallel_historycal_financial_reports' AIRFLOW_CTX_TASK_ID='financial_reports.run_main_report_1' AIRFLOW_CTX_EXECUTION_DATE='2024-12-09T10:07:06.230150+00:00' AIRFLOW_CTX_TRY_NUMBER='1' AIRFLOW_CTX_DAG_RUN_ID='manual__2024-12-09T10:07:06.230150+00:00'
[2024-12-09T10:07:15.594+0000] {taskinstance.py:731} INFO - ::endgroup::
[2024-12-09T10:07:36.984+0000] {taskinstance.py:3311} ERROR - Task failed with exception
Traceback (most recent call last):
  File "/usr/local/lib/python3.12/site-packages/airflow/models/taskinstance.py", line 767, in _execute_task
    result = _execute_callable(context=context, **execute_callable_kwargs)
             ^^^^^^^^^^^^^^^^^^^^^^^^^^^^^^^^^^^^^^^^^^^^^^^^^^^^^^^^^^^^^
  File "/usr/local/lib/python3.12/site-packages/airflow/models/taskinstance.py", line 733, in _execute_callable
    return ExecutionCallableRunner(
           ^^^^^^^^^^^^^^^^^^^^^^^^
  File "/usr/local/lib/python3.12/site-packages/airflow/utils/operator_helpers.py", line 252, in run
    return self.func(*args, **kwargs)
           ^^^^^^^^^^^^^^^^^^^^^^^^^^
  File "/usr/local/lib/python3.12/site-packages/airflow/models/baseoperator.py", line 417, in wrapper
    return func(self, *args, **kwargs)
           ^^^^^^^^^^^^^^^^^^^^^^^^^^^
  File "/usr/local/lib/python3.12/site-packages/airflow/operators/python.py", line 238, in execute
    return_value = self.execute_callable()
                   ^^^^^^^^^^^^^^^^^^^^^^^
  File "/usr/local/lib/python3.12/site-packages/airflow/operators/python.py", line 256, in execute_callable
    return runner.run(*self.op_args, **self.op_kwargs)
           ^^^^^^^^^^^^^^^^^^^^^^^^^^^^^^^^^^^^^^^^^^^
  File "/usr/local/lib/python3.12/site-packages/airflow/utils/operator_helpers.py", line 252, in run
    return self.func(*args, **kwargs)
           ^^^^^^^^^^^^^^^^^^^^^^^^^^
  File "/opt/Tasks/HistoricalData/company_financial_1.py", line 26, in main_report_1
    select_option_Xpath(driver, "(//div[contains(@class,'list-filter')]//button)[1]")
  File "/opt/ScrapingPackage/navigation.py", line 14, in select_option_Xpath
    option = WebDriverWait(driver, 60).until(
             ^^^^^^^^^^^^^^^^^^^^^^^^^^^^^^^^
  File "/usr/local/lib/python3.12/site-packages/selenium/webdriver/support/wait.py", line 86, in until
    value = method(self._driver)
            ^^^^^^^^^^^^^^^^^^^^
  File "/usr/local/lib/python3.12/site-packages/selenium/webdriver/support/expected_conditions.py", line 355, in _predicate
    target = visibility_of(target)(driver)
             ^^^^^^^^^^^^^^^^^^^^^^^^^^^^^
  File "/usr/local/lib/python3.12/site-packages/selenium/webdriver/support/expected_conditions.py", line 168, in _predicate
    return _element_if_visible(element)
           ^^^^^^^^^^^^^^^^^^^^^^^^^^^^
  File "/usr/local/lib/python3.12/site-packages/selenium/webdriver/support/expected_conditions.py", line 174, in _element_if_visible
    return element if element.is_displayed() == visibility else False
                      ^^^^^^^^^^^^^^^^^^^^^^
  File "/usr/local/lib/python3.12/site-packages/selenium/webdriver/remote/webelement.py", line 251, in is_displayed
    return self.parent.execute_script(f"/* isDisplayed */return ({isDisplayed_js}).apply(null, arguments);", self)
           ^^^^^^^^^^^^^^^^^^^^^^^^^^^^^^^^^^^^^^^^^^^^^^^^^^^^^^^^^^^^^^^^^^^^^^^^^^^^^^^^^^^^^^^^^^^^^^^^^^^^^^^
  File "/usr/local/lib/python3.12/site-packages/selenium/webdriver/remote/webdriver.py", line 404, in execute_script
    return self.execute(command, {"script": script, "args": converted_args})["value"]
           ^^^^^^^^^^^^^^^^^^^^^^^^^^^^^^^^^^^^^^^^^^^^^^^^^^^^^^^^^^^^^^^^^
  File "/usr/local/lib/python3.12/site-packages/selenium/webdriver/remote/webdriver.py", line 344, in execute
    self.error_handler.check_response(response)
  File "/usr/local/lib/python3.12/site-packages/selenium/webdriver/remote/errorhandler.py", line 229, in check_response
    raise exception_class(message, screen, stacktrace)
selenium.common.exceptions.StaleElementReferenceException: Message: stale element reference: stale element not found
  (Session info: chrome=131.0.6778.85); For documentation on this error, please visit: https://www.selenium.dev/documentation/webdriver/troubleshooting/errors#stale-element-reference-exception
Stacktrace:
#0 0x5619f7ff531a <unknown>
#1 0x5619f7b0b6e0 <unknown>
#2 0x5619f7b1cfbb <unknown>
#3 0x5619f7b1bd45 <unknown>
#4 0x5619f7b11d39 <unknown>
#5 0x5619f7b11e65 <unknown>
#6 0x5619f7b100a0 <unknown>
#7 0x5619f7b13c3e <unknown>
#8 0x5619f7b9df6c <unknown>
#9 0x5619f7b7e462 <unknown>
#10 0x5619f7b9ced7 <unknown>
#11 0x5619f7b7e203 <unknown>
#12 0x5619f7b4ccc0 <unknown>
#13 0x5619f7b4dc9e <unknown>
#14 0x5619f7fc2d0b <unknown>
#15 0x5619f7fc6c92 <unknown>
#16 0x5619f7fafb3c <unknown>
#17 0x5619f7fc7807 <unknown>
#18 0x5619f7f950df <unknown>
#19 0x5619f7fe4578 <unknown>
#20 0x5619f7fe4740 <unknown>
#21 0x5619f7ff4196 <unknown>
#22 0x7f9a2b5b3a94 <unknown>
#23 0x7f9a2b640c3c <unknown>

[2024-12-09T10:07:37.149+0000] {taskinstance.py:1225} INFO - Marking task as FAILED. dag_id=parallel_historycal_financial_reports, task_id=financial_reports.run_main_report_1, run_id=manual__2024-12-09T10:07:06.230150+00:00, execution_date=20241209T100706, start_date=20241209T100714, end_date=20241209T100737
[2024-12-09T10:07:37.245+0000] {taskinstance.py:340} INFO - ::group::Post task execution logs
[2024-12-09T10:07:37.246+0000] {standard_task_runner.py:124} ERROR - Failed to execute job 203 for task financial_reports.run_main_report_1 (Message: stale element reference: stale element not found
  (Session info: chrome=131.0.6778.85); For documentation on this error, please visit: https://www.selenium.dev/documentation/webdriver/troubleshooting/errors#stale-element-reference-exception
Stacktrace:
#0 0x5619f7ff531a <unknown>
#1 0x5619f7b0b6e0 <unknown>
#2 0x5619f7b1cfbb <unknown>
#3 0x5619f7b1bd45 <unknown>
#4 0x5619f7b11d39 <unknown>
#5 0x5619f7b11e65 <unknown>
#6 0x5619f7b100a0 <unknown>
#7 0x5619f7b13c3e <unknown>
#8 0x5619f7b9df6c <unknown>
#9 0x5619f7b7e462 <unknown>
#10 0x5619f7b9ced7 <unknown>
#11 0x5619f7b7e203 <unknown>
#12 0x5619f7b4ccc0 <unknown>
#13 0x5619f7b4dc9e <unknown>
#14 0x5619f7fc2d0b <unknown>
#15 0x5619f7fc6c92 <unknown>
#16 0x5619f7fafb3c <unknown>
#17 0x5619f7fc7807 <unknown>
#18 0x5619f7f950df <unknown>
#19 0x5619f7fe4578 <unknown>
#20 0x5619f7fe4740 <unknown>
#21 0x5619f7ff4196 <unknown>
#22 0x7f9a2b5b3a94 <unknown>
#23 0x7f9a2b640c3c <unknown>
; 619)
Traceback (most recent call last):
  File "/usr/local/lib/python3.12/site-packages/airflow/task/task_runner/standard_task_runner.py", line 117, in _start_by_fork
    ret = args.func(args, dag=self.dag)
          ^^^^^^^^^^^^^^^^^^^^^^^^^^^^^
  File "/usr/local/lib/python3.12/site-packages/airflow/cli/cli_config.py", line 49, in command
    return func(*args, **kwargs)
           ^^^^^^^^^^^^^^^^^^^^^
  File "/usr/local/lib/python3.12/site-packages/airflow/utils/cli.py", line 116, in wrapper
    return f(*args, **kwargs)
           ^^^^^^^^^^^^^^^^^^
  File "/usr/local/lib/python3.12/site-packages/airflow/cli/commands/task_command.py", line 483, in task_run
    task_return_code = _run_task_by_selected_method(args, _dag, ti)
                       ^^^^^^^^^^^^^^^^^^^^^^^^^^^^^^^^^^^^^^^^^^^^
  File "/usr/local/lib/python3.12/site-packages/airflow/cli/commands/task_command.py", line 256, in _run_task_by_selected_method
    return _run_raw_task(args, ti)
           ^^^^^^^^^^^^^^^^^^^^^^^
  File "/usr/local/lib/python3.12/site-packages/airflow/cli/commands/task_command.py", line 341, in _run_raw_task
    return ti._run_raw_task(
           ^^^^^^^^^^^^^^^^^
  File "/usr/local/lib/python3.12/site-packages/airflow/utils/session.py", line 97, in wrapper
    return func(*args, session=session, **kwargs)
           ^^^^^^^^^^^^^^^^^^^^^^^^^^^^^^^^^^^^^^
  File "/usr/local/lib/python3.12/site-packages/airflow/models/taskinstance.py", line 3005, in _run_raw_task
    return _run_raw_task(
           ^^^^^^^^^^^^^^
  File "/usr/local/lib/python3.12/site-packages/airflow/models/taskinstance.py", line 273, in _run_raw_task
    TaskInstance._execute_task_with_callbacks(
  File "/usr/local/lib/python3.12/site-packages/airflow/models/taskinstance.py", line 3159, in _execute_task_with_callbacks
    result = self._execute_task(context, task_orig)
             ^^^^^^^^^^^^^^^^^^^^^^^^^^^^^^^^^^^^^^
  File "/usr/local/lib/python3.12/site-packages/airflow/models/taskinstance.py", line 3183, in _execute_task
    return _execute_task(self, context, task_orig)
           ^^^^^^^^^^^^^^^^^^^^^^^^^^^^^^^^^^^^^^^
  File "/usr/local/lib/python3.12/site-packages/airflow/models/taskinstance.py", line 767, in _execute_task
    result = _execute_callable(context=context, **execute_callable_kwargs)
             ^^^^^^^^^^^^^^^^^^^^^^^^^^^^^^^^^^^^^^^^^^^^^^^^^^^^^^^^^^^^^
  File "/usr/local/lib/python3.12/site-packages/airflow/models/taskinstance.py", line 733, in _execute_callable
    return ExecutionCallableRunner(
           ^^^^^^^^^^^^^^^^^^^^^^^^
  File "/usr/local/lib/python3.12/site-packages/airflow/utils/operator_helpers.py", line 252, in run
    return self.func(*args, **kwargs)
           ^^^^^^^^^^^^^^^^^^^^^^^^^^
  File "/usr/local/lib/python3.12/site-packages/airflow/models/baseoperator.py", line 417, in wrapper
    return func(self, *args, **kwargs)
           ^^^^^^^^^^^^^^^^^^^^^^^^^^^
  File "/usr/local/lib/python3.12/site-packages/airflow/operators/python.py", line 238, in execute
    return_value = self.execute_callable()
                   ^^^^^^^^^^^^^^^^^^^^^^^
  File "/usr/local/lib/python3.12/site-packages/airflow/operators/python.py", line 256, in execute_callable
    return runner.run(*self.op_args, **self.op_kwargs)
           ^^^^^^^^^^^^^^^^^^^^^^^^^^^^^^^^^^^^^^^^^^^
  File "/usr/local/lib/python3.12/site-packages/airflow/utils/operator_helpers.py", line 252, in run
    return self.func(*args, **kwargs)
           ^^^^^^^^^^^^^^^^^^^^^^^^^^
  File "/opt/Tasks/HistoricalData/company_financial_1.py", line 26, in main_report_1
    select_option_Xpath(driver, "(//div[contains(@class,'list-filter')]//button)[1]")
  File "/opt/ScrapingPackage/navigation.py", line 14, in select_option_Xpath
    option = WebDriverWait(driver, 60).until(
             ^^^^^^^^^^^^^^^^^^^^^^^^^^^^^^^^
  File "/usr/local/lib/python3.12/site-packages/selenium/webdriver/support/wait.py", line 86, in until
    value = method(self._driver)
            ^^^^^^^^^^^^^^^^^^^^
  File "/usr/local/lib/python3.12/site-packages/selenium/webdriver/support/expected_conditions.py", line 355, in _predicate
    target = visibility_of(target)(driver)
             ^^^^^^^^^^^^^^^^^^^^^^^^^^^^^
  File "/usr/local/lib/python3.12/site-packages/selenium/webdriver/support/expected_conditions.py", line 168, in _predicate
    return _element_if_visible(element)
           ^^^^^^^^^^^^^^^^^^^^^^^^^^^^
  File "/usr/local/lib/python3.12/site-packages/selenium/webdriver/support/expected_conditions.py", line 174, in _element_if_visible
    return element if element.is_displayed() == visibility else False
                      ^^^^^^^^^^^^^^^^^^^^^^
  File "/usr/local/lib/python3.12/site-packages/selenium/webdriver/remote/webelement.py", line 251, in is_displayed
    return self.parent.execute_script(f"/* isDisplayed */return ({isDisplayed_js}).apply(null, arguments);", self)
           ^^^^^^^^^^^^^^^^^^^^^^^^^^^^^^^^^^^^^^^^^^^^^^^^^^^^^^^^^^^^^^^^^^^^^^^^^^^^^^^^^^^^^^^^^^^^^^^^^^^^^^^
  File "/usr/local/lib/python3.12/site-packages/selenium/webdriver/remote/webdriver.py", line 404, in execute_script
    return self.execute(command, {"script": script, "args": converted_args})["value"]
           ^^^^^^^^^^^^^^^^^^^^^^^^^^^^^^^^^^^^^^^^^^^^^^^^^^^^^^^^^^^^^^^^^
  File "/usr/local/lib/python3.12/site-packages/selenium/webdriver/remote/webdriver.py", line 344, in execute
    self.error_handler.check_response(response)
  File "/usr/local/lib/python3.12/site-packages/selenium/webdriver/remote/errorhandler.py", line 229, in check_response
    raise exception_class(message, screen, stacktrace)
selenium.common.exceptions.StaleElementReferenceException: Message: stale element reference: stale element not found
  (Session info: chrome=131.0.6778.85); For documentation on this error, please visit: https://www.selenium.dev/documentation/webdriver/troubleshooting/errors#stale-element-reference-exception
Stacktrace:
#0 0x5619f7ff531a <unknown>
#1 0x5619f7b0b6e0 <unknown>
#2 0x5619f7b1cfbb <unknown>
#3 0x5619f7b1bd45 <unknown>
#4 0x5619f7b11d39 <unknown>
#5 0x5619f7b11e65 <unknown>
#6 0x5619f7b100a0 <unknown>
#7 0x5619f7b13c3e <unknown>
#8 0x5619f7b9df6c <unknown>
#9 0x5619f7b7e462 <unknown>
#10 0x5619f7b9ced7 <unknown>
#11 0x5619f7b7e203 <unknown>
#12 0x5619f7b4ccc0 <unknown>
#13 0x5619f7b4dc9e <unknown>
#14 0x5619f7fc2d0b <unknown>
#15 0x5619f7fc6c92 <unknown>
#16 0x5619f7fafb3c <unknown>
#17 0x5619f7fc7807 <unknown>
#18 0x5619f7f950df <unknown>
#19 0x5619f7fe4578 <unknown>
#20 0x5619f7fe4740 <unknown>
#21 0x5619f7ff4196 <unknown>
#22 0x7f9a2b5b3a94 <unknown>
#23 0x7f9a2b640c3c <unknown>

[2024-12-09T10:07:37.270+0000] {local_task_job_runner.py:266} INFO - Task exited with return code 1
[2024-12-09T10:07:37.336+0000] {taskinstance.py:3895} INFO - 0 downstream tasks scheduled from follow-on schedule check
[2024-12-09T10:07:37.347+0000] {local_task_job_runner.py:245} INFO - ::endgroup::
