[2024-12-12T05:04:01.363+0000] {local_task_job_runner.py:123} INFO - ::group::Pre task execution logs
[2024-12-12T05:04:01.448+0000] {taskinstance.py:2613} INFO - Dependencies all met for dep_context=non-requeueable deps ti=<TaskInstance: parallel_new_price_with_group.process_groups.process_group_3 scheduled__2024-12-10T20:00:00+00:00 [queued]>
[2024-12-12T05:04:01.469+0000] {taskinstance.py:2613} INFO - Dependencies all met for dep_context=requeueable deps ti=<TaskInstance: parallel_new_price_with_group.process_groups.process_group_3 scheduled__2024-12-10T20:00:00+00:00 [queued]>
[2024-12-12T05:04:01.470+0000] {taskinstance.py:2866} INFO - Starting attempt 1 of 2
[2024-12-12T05:04:01.533+0000] {taskinstance.py:2889} INFO - Executing <Task(PythonOperator): process_groups.process_group_3> on 2024-12-10 20:00:00+00:00
[2024-12-12T05:04:01.558+0000] {logging_mixin.py:190} WARNING - /usr/local/lib/python3.12/site-packages/airflow/task/task_runner/standard_task_runner.py:70 DeprecationWarning: This process (pid=4717) is multi-threaded, use of fork() may lead to deadlocks in the child.
[2024-12-12T05:04:01.561+0000] {standard_task_runner.py:72} INFO - Started process 4748 to run task
[2024-12-12T05:04:01.558+0000] {standard_task_runner.py:104} INFO - Running: ['airflow', 'tasks', 'run', 'parallel_new_price_with_group', 'process_groups.process_group_3', 'scheduled__2024-12-10T20:00:00+00:00', '--job-id', '257', '--raw', '--subdir', 'DAGS_FOLDER/Extract_new_price_data.py', '--cfg-path', '/tmp/tmpknqutl7l']
[2024-12-12T05:04:01.563+0000] {standard_task_runner.py:105} INFO - Job 257: Subtask process_groups.process_group_3
[2024-12-12T05:04:01.812+0000] {task_command.py:467} INFO - Running <TaskInstance: parallel_new_price_with_group.process_groups.process_group_3 scheduled__2024-12-10T20:00:00+00:00 [running]> on host b97e805017e1
[2024-12-12T05:04:02.388+0000] {taskinstance.py:3132} INFO - Exporting env vars: AIRFLOW_CTX_DAG_OWNER='airflowDWH' AIRFLOW_CTX_DAG_ID='parallel_new_price_with_group' AIRFLOW_CTX_TASK_ID='process_groups.process_group_3' AIRFLOW_CTX_EXECUTION_DATE='2024-12-10T20:00:00+00:00' AIRFLOW_CTX_TRY_NUMBER='1' AIRFLOW_CTX_DAG_RUN_ID='scheduled__2024-12-10T20:00:00+00:00'
[2024-12-12T05:04:02.393+0000] {taskinstance.py:731} INFO - ::endgroup::
[2024-12-12T05:04:09.457+0000] {data_explorer.py:64} WARNING - Thông tin niêm yết & giao dịch sẽ được truy xuất từ TCBS
[2024-12-12T05:04:11.301+0000] {data_explorer.py:64} WARNING - Thông tin niêm yết & giao dịch sẽ được truy xuất từ TCBS
[2024-12-12T05:04:12.327+0000] {data_explorer.py:64} WARNING - Thông tin niêm yết & giao dịch sẽ được truy xuất từ TCBS
[2024-12-12T05:04:13.356+0000] {data_explorer.py:64} WARNING - Thông tin niêm yết & giao dịch sẽ được truy xuất từ TCBS
[2024-12-12T05:04:13.681+0000] {logging_mixin.py:190} INFO - Mã cổ phiếu TBR hiện bị dừng giao dịch
[2024-12-12T05:04:14.631+0000] {data_explorer.py:64} WARNING - Thông tin niêm yết & giao dịch sẽ được truy xuất từ TCBS
[2024-12-12T05:04:15.778+0000] {data_explorer.py:64} WARNING - Thông tin niêm yết & giao dịch sẽ được truy xuất từ TCBS
[2024-12-12T05:04:17.183+0000] {data_explorer.py:64} WARNING - Thông tin niêm yết & giao dịch sẽ được truy xuất từ TCBS
[2024-12-12T05:04:18.289+0000] {data_explorer.py:64} WARNING - Thông tin niêm yết & giao dịch sẽ được truy xuất từ TCBS
[2024-12-12T05:04:19.446+0000] {data_explorer.py:64} WARNING - Thông tin niêm yết & giao dịch sẽ được truy xuất từ TCBS
[2024-12-12T05:04:19.924+0000] {logging_mixin.py:190} INFO - Mã cổ phiếu LMH hiện bị dừng giao dịch
[2024-12-12T05:04:20.642+0000] {data_explorer.py:64} WARNING - Thông tin niêm yết & giao dịch sẽ được truy xuất từ TCBS
[2024-12-12T05:04:21.588+0000] {data_explorer.py:64} WARNING - Thông tin niêm yết & giao dịch sẽ được truy xuất từ TCBS
[2024-12-12T05:04:22.577+0000] {data_explorer.py:64} WARNING - Thông tin niêm yết & giao dịch sẽ được truy xuất từ TCBS
[2024-12-12T05:04:23.887+0000] {data_explorer.py:64} WARNING - Thông tin niêm yết & giao dịch sẽ được truy xuất từ TCBS
[2024-12-12T05:04:24.139+0000] {logging_mixin.py:190} INFO - Mã cổ phiếu PVR hiện bị dừng giao dịch
[2024-12-12T05:04:24.860+0000] {data_explorer.py:64} WARNING - Thông tin niêm yết & giao dịch sẽ được truy xuất từ TCBS
[2024-12-12T05:04:26.063+0000] {data_explorer.py:64} WARNING - Thông tin niêm yết & giao dịch sẽ được truy xuất từ TCBS
[2024-12-12T05:04:27.304+0000] {data_explorer.py:64} WARNING - Thông tin niêm yết & giao dịch sẽ được truy xuất từ TCBS
[2024-12-12T05:04:28.550+0000] {data_explorer.py:64} WARNING - Thông tin niêm yết & giao dịch sẽ được truy xuất từ TCBS
[2024-12-12T05:04:29.062+0000] {logging_mixin.py:190} INFO - Mã cổ phiếu PXC hiện bị dừng giao dịch
[2024-12-12T05:04:30.655+0000] {data_explorer.py:64} WARNING - Thông tin niêm yết & giao dịch sẽ được truy xuất từ TCBS
[2024-12-12T05:04:32.945+0000] {data_explorer.py:64} WARNING - Thông tin niêm yết & giao dịch sẽ được truy xuất từ TCBS
[2024-12-12T05:04:33.426+0000] {logging_mixin.py:190} INFO - Mã cổ phiếu SZG hiện bị dừng giao dịch
[2024-12-12T05:04:34.513+0000] {data_explorer.py:64} WARNING - Thông tin niêm yết & giao dịch sẽ được truy xuất từ TCBS
[2024-12-12T05:04:35.887+0000] {data_explorer.py:64} WARNING - Thông tin niêm yết & giao dịch sẽ được truy xuất từ TCBS
[2024-12-12T05:04:36.454+0000] {logging_mixin.py:190} INFO - Mã cổ phiếu STL hiện bị dừng giao dịch
[2024-12-12T05:04:47.865+0000] {logging_mixin.py:190} INFO - Mã cổ phiếu SZL hiện bị dừng giao dịch
[2024-12-12T05:04:47.774+0000] {job.py:239} ERROR - Job heartbeat failed with error
Traceback (most recent call last):
  File "/usr/local/lib/python3.12/site-packages/sqlalchemy/engine/base.py", line 3371, in _wrap_pool_connect
    return fn()
           ^^^^
  File "/usr/local/lib/python3.12/site-packages/sqlalchemy/pool/base.py", line 327, in connect
    return _ConnectionFairy._checkout(self)
           ^^^^^^^^^^^^^^^^^^^^^^^^^^^^^^^^
  File "/usr/local/lib/python3.12/site-packages/sqlalchemy/pool/base.py", line 894, in _checkout
    fairy = _ConnectionRecord.checkout(pool)
            ^^^^^^^^^^^^^^^^^^^^^^^^^^^^^^^^
  File "/usr/local/lib/python3.12/site-packages/sqlalchemy/pool/base.py", line 493, in checkout
    rec = pool._do_get()
          ^^^^^^^^^^^^^^
  File "/usr/local/lib/python3.12/site-packages/sqlalchemy/pool/impl.py", line 256, in _do_get
    return self._create_connection()
           ^^^^^^^^^^^^^^^^^^^^^^^^^
  File "/usr/local/lib/python3.12/site-packages/sqlalchemy/pool/base.py", line 273, in _create_connection
    return _ConnectionRecord(self)
           ^^^^^^^^^^^^^^^^^^^^^^^
  File "/usr/local/lib/python3.12/site-packages/sqlalchemy/pool/base.py", line 388, in __init__
    self.__connect()
  File "/usr/local/lib/python3.12/site-packages/sqlalchemy/pool/base.py", line 690, in __connect
    with util.safe_reraise():
         ^^^^^^^^^^^^^^^^^^^
  File "/usr/local/lib/python3.12/site-packages/sqlalchemy/util/langhelpers.py", line 70, in __exit__
    compat.raise_(
  File "/usr/local/lib/python3.12/site-packages/sqlalchemy/util/compat.py", line 211, in raise_
    raise exception
  File "/usr/local/lib/python3.12/site-packages/sqlalchemy/pool/base.py", line 686, in __connect
    self.dbapi_connection = connection = pool._invoke_creator(self)
                                         ^^^^^^^^^^^^^^^^^^^^^^^^^^
  File "/usr/local/lib/python3.12/site-packages/sqlalchemy/engine/create.py", line 574, in connect
    return dialect.connect(*cargs, **cparams)
           ^^^^^^^^^^^^^^^^^^^^^^^^^^^^^^^^^^
  File "/usr/local/lib/python3.12/site-packages/sqlalchemy/engine/default.py", line 598, in connect
    return self.dbapi.connect(*cargs, **cparams)
           ^^^^^^^^^^^^^^^^^^^^^^^^^^^^^^^^^^^^^
  File "/usr/local/lib/python3.12/site-packages/psycopg2/__init__.py", line 122, in connect
    conn = _connect(dsn, connection_factory=connection_factory, **kwasync)
           ^^^^^^^^^^^^^^^^^^^^^^^^^^^^^^^^^^^^^^^^^^^^^^^^^^^^^^^^^^^^^^^
psycopg2.OperationalError: could not translate host name "host.docker.internal" to address: Temporary failure in name resolution


The above exception was the direct cause of the following exception:

Traceback (most recent call last):
  File "/usr/local/lib/python3.12/site-packages/airflow/jobs/job.py", line 233, in heartbeat
    heartbeat_callback(session)
  File "/usr/local/lib/python3.12/site-packages/airflow/utils/session.py", line 94, in wrapper
    return func(*args, **kwargs)
           ^^^^^^^^^^^^^^^^^^^^^
  File "/usr/local/lib/python3.12/site-packages/airflow/jobs/local_task_job_runner.py", line 284, in heartbeat_callback
    self.task_instance.refresh_from_db()
  File "/usr/local/lib/python3.12/site-packages/airflow/utils/session.py", line 97, in wrapper
    return func(*args, session=session, **kwargs)
           ^^^^^^^^^^^^^^^^^^^^^^^^^^^^^^^^^^^^^^
  File "/usr/local/lib/python3.12/site-packages/airflow/models/taskinstance.py", line 2359, in refresh_from_db
    _refresh_from_db(task_instance=self, session=session, lock_for_update=lock_for_update)
  File "/usr/local/lib/python3.12/site-packages/airflow/models/taskinstance.py", line 872, in _refresh_from_db
    ti = TaskInstance.get_task_instance(
         ^^^^^^^^^^^^^^^^^^^^^^^^^^^^^^^
  File "/usr/local/lib/python3.12/site-packages/airflow/api_internal/internal_api_call.py", line 166, in wrapper
    return func(*args, **kwargs)
           ^^^^^^^^^^^^^^^^^^^^^
  File "/usr/local/lib/python3.12/site-packages/airflow/utils/session.py", line 94, in wrapper
    return func(*args, **kwargs)
           ^^^^^^^^^^^^^^^^^^^^^
  File "/usr/local/lib/python3.12/site-packages/airflow/models/taskinstance.py", line 2345, in get_task_instance
    return query.one_or_none()
           ^^^^^^^^^^^^^^^^^^^
  File "/usr/local/lib/python3.12/site-packages/sqlalchemy/orm/query.py", line 2850, in one_or_none
    return self._iter().one_or_none()
           ^^^^^^^^^^^^
  File "/usr/local/lib/python3.12/site-packages/sqlalchemy/orm/query.py", line 2916, in _iter
    result = self.session.execute(
             ^^^^^^^^^^^^^^^^^^^^^
  File "/usr/local/lib/python3.12/site-packages/sqlalchemy/orm/session.py", line 1716, in execute
    conn = self._connection_for_bind(bind)
           ^^^^^^^^^^^^^^^^^^^^^^^^^^^^^^^
  File "/usr/local/lib/python3.12/site-packages/sqlalchemy/orm/session.py", line 1555, in _connection_for_bind
    return self._transaction._connection_for_bind(
           ^^^^^^^^^^^^^^^^^^^^^^^^^^^^^^^^^^^^^^^
  File "/usr/local/lib/python3.12/site-packages/sqlalchemy/orm/session.py", line 750, in _connection_for_bind
    conn = bind.connect()
           ^^^^^^^^^^^^^^
  File "/usr/local/lib/python3.12/site-packages/sqlalchemy/future/engine.py", line 412, in connect
    return super(Engine, self).connect()
           ^^^^^^^^^^^^^^^^^^^^^^^^^^^^^
  File "/usr/local/lib/python3.12/site-packages/sqlalchemy/engine/base.py", line 3325, in connect
    return self._connection_cls(self, close_with_result=close_with_result)
           ^^^^^^^^^^^^^^^^^^^^^^^^^^^^^^^^^^^^^^^^^^^^^^^^^^^^^^^^^^^^^^^
  File "/usr/local/lib/python3.12/site-packages/sqlalchemy/engine/base.py", line 96, in __init__
    else engine.raw_connection()
         ^^^^^^^^^^^^^^^^^^^^^^^
  File "/usr/local/lib/python3.12/site-packages/sqlalchemy/engine/base.py", line 3404, in raw_connection
    return self._wrap_pool_connect(self.pool.connect, _connection)
           ^^^^^^^^^^^^^^^^^^^^^^^^^^^^^^^^^^^^^^^^^^^^^^^^^^^^^^^
  File "/usr/local/lib/python3.12/site-packages/sqlalchemy/engine/base.py", line 3374, in _wrap_pool_connect
    Connection._handle_dbapi_exception_noconnection(
  File "/usr/local/lib/python3.12/site-packages/sqlalchemy/engine/base.py", line 2208, in _handle_dbapi_exception_noconnection
    util.raise_(
  File "/usr/local/lib/python3.12/site-packages/sqlalchemy/util/compat.py", line 211, in raise_
    raise exception
  File "/usr/local/lib/python3.12/site-packages/sqlalchemy/engine/base.py", line 3371, in _wrap_pool_connect
    return fn()
           ^^^^
  File "/usr/local/lib/python3.12/site-packages/sqlalchemy/pool/base.py", line 327, in connect
    return _ConnectionFairy._checkout(self)
           ^^^^^^^^^^^^^^^^^^^^^^^^^^^^^^^^
  File "/usr/local/lib/python3.12/site-packages/sqlalchemy/pool/base.py", line 894, in _checkout
    fairy = _ConnectionRecord.checkout(pool)
            ^^^^^^^^^^^^^^^^^^^^^^^^^^^^^^^^
  File "/usr/local/lib/python3.12/site-packages/sqlalchemy/pool/base.py", line 493, in checkout
    rec = pool._do_get()
          ^^^^^^^^^^^^^^
  File "/usr/local/lib/python3.12/site-packages/sqlalchemy/pool/impl.py", line 256, in _do_get
    return self._create_connection()
           ^^^^^^^^^^^^^^^^^^^^^^^^^
  File "/usr/local/lib/python3.12/site-packages/sqlalchemy/pool/base.py", line 273, in _create_connection
    return _ConnectionRecord(self)
           ^^^^^^^^^^^^^^^^^^^^^^^
  File "/usr/local/lib/python3.12/site-packages/sqlalchemy/pool/base.py", line 388, in __init__
    self.__connect()
  File "/usr/local/lib/python3.12/site-packages/sqlalchemy/pool/base.py", line 690, in __connect
    with util.safe_reraise():
         ^^^^^^^^^^^^^^^^^^^
  File "/usr/local/lib/python3.12/site-packages/sqlalchemy/util/langhelpers.py", line 70, in __exit__
    compat.raise_(
  File "/usr/local/lib/python3.12/site-packages/sqlalchemy/util/compat.py", line 211, in raise_
    raise exception
  File "/usr/local/lib/python3.12/site-packages/sqlalchemy/pool/base.py", line 686, in __connect
    self.dbapi_connection = connection = pool._invoke_creator(self)
                                         ^^^^^^^^^^^^^^^^^^^^^^^^^^
  File "/usr/local/lib/python3.12/site-packages/sqlalchemy/engine/create.py", line 574, in connect
    return dialect.connect(*cargs, **cparams)
           ^^^^^^^^^^^^^^^^^^^^^^^^^^^^^^^^^^
  File "/usr/local/lib/python3.12/site-packages/sqlalchemy/engine/default.py", line 598, in connect
    return self.dbapi.connect(*cargs, **cparams)
           ^^^^^^^^^^^^^^^^^^^^^^^^^^^^^^^^^^^^^
  File "/usr/local/lib/python3.12/site-packages/psycopg2/__init__.py", line 122, in connect
    conn = _connect(dsn, connection_factory=connection_factory, **kwasync)
           ^^^^^^^^^^^^^^^^^^^^^^^^^^^^^^^^^^^^^^^^^^^^^^^^^^^^^^^^^^^^^^^
sqlalchemy.exc.OperationalError: (psycopg2.OperationalError) could not translate host name "host.docker.internal" to address: Temporary failure in name resolution

(Background on this error at: https://sqlalche.me/e/14/e3q8)
[2024-12-12T05:04:48.639+0000] {job.py:254} ERROR - Job heartbeat failed with error. Scheduler is in unhealthy state
[2024-12-12T05:04:52.714+0000] {data_explorer.py:64} WARNING - Thông tin niêm yết & giao dịch sẽ được truy xuất từ TCBS
[2024-12-12T05:04:55.315+0000] {job.py:229} INFO - Heartbeat recovered after 18.68 seconds
[2024-12-12T05:04:57.127+0000] {data_explorer.py:64} WARNING - Thông tin niêm yết & giao dịch sẽ được truy xuất từ TCBS
[2024-12-12T05:04:59.093+0000] {data_explorer.py:64} WARNING - Thông tin niêm yết & giao dịch sẽ được truy xuất từ TCBS
[2024-12-12T05:05:01.717+0000] {data_explorer.py:64} WARNING - Thông tin niêm yết & giao dịch sẽ được truy xuất từ TCBS
[2024-12-12T05:05:02.804+0000] {python.py:240} INFO - Done. Returned value was: None
[2024-12-12T05:05:04.335+0000] {taskinstance.py:340} INFO - ::group::Post task execution logs
[2024-12-12T05:05:04.369+0000] {taskinstance.py:352} INFO - Marking task as SUCCESS. dag_id=parallel_new_price_with_group, task_id=process_groups.process_group_3, run_id=scheduled__2024-12-10T20:00:00+00:00, execution_date=20241210T200000, start_date=20241212T050401, end_date=20241212T050504
[2024-12-12T05:05:06.292+0000] {local_task_job_runner.py:266} INFO - Task exited with return code 0
[2024-12-12T05:05:06.507+0000] {standard_task_runner.py:217} INFO - Process not found (most likely exited), stop collecting metrics
[2024-12-12T05:05:06.837+0000] {taskinstance.py:3895} INFO - 0 downstream tasks scheduled from follow-on schedule check
[2024-12-12T05:05:06.846+0000] {local_task_job_runner.py:245} INFO - ::endgroup::
