[2024-12-13T17:18:33.809+0000] {local_task_job_runner.py:123} INFO - ::group::Pre task execution logs
[2024-12-13T17:18:33.853+0000] {taskinstance.py:2613} INFO - Dependencies all met for dep_context=non-requeueable deps ti=<TaskInstance: load_company_info_to_staging_db.Staging_to_Datawarehouse manual__2024-12-13T17:18:25.585985+00:00 [queued]>
[2024-12-13T17:18:33.917+0000] {taskinstance.py:2613} INFO - Dependencies all met for dep_context=requeueable deps ti=<TaskInstance: load_company_info_to_staging_db.Staging_to_Datawarehouse manual__2024-12-13T17:18:25.585985+00:00 [queued]>
[2024-12-13T17:18:33.918+0000] {taskinstance.py:2866} INFO - Starting attempt 1 of 1
[2024-12-13T17:18:33.936+0000] {taskinstance.py:2889} INFO - Executing <Task(PythonOperator): Staging_to_Datawarehouse> on 2024-12-13 17:18:25.585985+00:00
[2024-12-13T17:18:33.946+0000] {logging_mixin.py:190} WARNING - /usr/local/lib/python3.12/site-packages/airflow/task/task_runner/standard_task_runner.py:70 DeprecationWarning: This process (pid=3169) is multi-threaded, use of fork() may lead to deadlocks in the child.
[2024-12-13T17:18:33.945+0000] {standard_task_runner.py:104} INFO - Running: ['airflow', 'tasks', 'run', 'load_company_info_to_staging_db', 'Staging_to_Datawarehouse', 'manual__2024-12-13T17:18:25.585985+00:00', '--job-id', '393', '--raw', '--subdir', 'DAGS_FOLDER/Load_company_info_to_staging.py', '--cfg-path', '/tmp/tmp0skoqah1']
[2024-12-13T17:18:33.947+0000] {standard_task_runner.py:105} INFO - Job 393: Subtask Staging_to_Datawarehouse
[2024-12-13T17:18:33.947+0000] {standard_task_runner.py:72} INFO - Started process 3170 to run task
[2024-12-13T17:18:34.043+0000] {task_command.py:467} INFO - Running <TaskInstance: load_company_info_to_staging_db.Staging_to_Datawarehouse manual__2024-12-13T17:18:25.585985+00:00 [running]> on host 2f7cc6f48508
[2024-12-13T17:18:34.248+0000] {taskinstance.py:3132} INFO - Exporting env vars: AIRFLOW_CTX_DAG_OWNER='airflowDWH' AIRFLOW_CTX_DAG_ID='load_company_info_to_staging_db' AIRFLOW_CTX_TASK_ID='Staging_to_Datawarehouse' AIRFLOW_CTX_EXECUTION_DATE='2024-12-13T17:18:25.585985+00:00' AIRFLOW_CTX_TRY_NUMBER='1' AIRFLOW_CTX_DAG_RUN_ID='manual__2024-12-13T17:18:25.585985+00:00'
[2024-12-13T17:18:34.251+0000] {taskinstance.py:731} INFO - ::endgroup::
[2024-12-13T17:18:34.302+0000] {base.py:84} INFO - Retrieving connection 'load_to_staging'
[2024-12-13T17:18:34.355+0000] {base.py:84} INFO - Retrieving connection 'load_to_dwh'
[2024-12-13T17:18:34.411+0000] {taskinstance.py:3311} ERROR - Task failed with exception
Traceback (most recent call last):
  File "/usr/local/lib/python3.12/site-packages/airflow/models/taskinstance.py", line 767, in _execute_task
    result = _execute_callable(context=context, **execute_callable_kwargs)
             ^^^^^^^^^^^^^^^^^^^^^^^^^^^^^^^^^^^^^^^^^^^^^^^^^^^^^^^^^^^^^
  File "/usr/local/lib/python3.12/site-packages/airflow/models/taskinstance.py", line 733, in _execute_callable
    return ExecutionCallableRunner(
           ^^^^^^^^^^^^^^^^^^^^^^^^
  File "/usr/local/lib/python3.12/site-packages/airflow/utils/operator_helpers.py", line 252, in run
    return self.func(*args, **kwargs)
           ^^^^^^^^^^^^^^^^^^^^^^^^^^
  File "/usr/local/lib/python3.12/site-packages/airflow/models/baseoperator.py", line 417, in wrapper
    return func(self, *args, **kwargs)
           ^^^^^^^^^^^^^^^^^^^^^^^^^^^
  File "/usr/local/lib/python3.12/site-packages/airflow/operators/python.py", line 238, in execute
    return_value = self.execute_callable()
                   ^^^^^^^^^^^^^^^^^^^^^^^
  File "/usr/local/lib/python3.12/site-packages/airflow/operators/python.py", line 256, in execute_callable
    return runner.run(*self.op_args, **self.op_kwargs)
           ^^^^^^^^^^^^^^^^^^^^^^^^^^^^^^^^^^^^^^^^^^^
  File "/usr/local/lib/python3.12/site-packages/airflow/utils/operator_helpers.py", line 252, in run
    return self.func(*args, **kwargs)
           ^^^^^^^^^^^^^^^^^^^^^^^^^^
  File "/opt/Tasks/transform_and_load_data/transform_and_load.py", line 40, in hosocongty_transform_and_load
    dwh_cursor.executemany(sql_insert, transformed_data)
psycopg2.errors.ForeignKeyViolation: insert or update on table "dim_company" violates foreign key constraint "dim_company_san_niem_yet_fkey"
DETAIL:  Key (san_niem_yet)=(Upcom) is not present in table "dim_exchange".

[2024-12-13T17:18:34.460+0000] {taskinstance.py:1225} INFO - Marking task as FAILED. dag_id=load_company_info_to_staging_db, task_id=Staging_to_Datawarehouse, run_id=manual__2024-12-13T17:18:25.585985+00:00, execution_date=20241213T171825, start_date=20241213T171833, end_date=20241213T171834
[2024-12-13T17:18:34.498+0000] {taskinstance.py:340} INFO - ::group::Post task execution logs
[2024-12-13T17:18:34.498+0000] {standard_task_runner.py:124} ERROR - Failed to execute job 393 for task Staging_to_Datawarehouse (insert or update on table "dim_company" violates foreign key constraint "dim_company_san_niem_yet_fkey"
DETAIL:  Key (san_niem_yet)=(Upcom) is not present in table "dim_exchange".
; 3170)
Traceback (most recent call last):
  File "/usr/local/lib/python3.12/site-packages/airflow/task/task_runner/standard_task_runner.py", line 117, in _start_by_fork
    ret = args.func(args, dag=self.dag)
          ^^^^^^^^^^^^^^^^^^^^^^^^^^^^^
  File "/usr/local/lib/python3.12/site-packages/airflow/cli/cli_config.py", line 49, in command
    return func(*args, **kwargs)
           ^^^^^^^^^^^^^^^^^^^^^
  File "/usr/local/lib/python3.12/site-packages/airflow/utils/cli.py", line 116, in wrapper
    return f(*args, **kwargs)
           ^^^^^^^^^^^^^^^^^^
  File "/usr/local/lib/python3.12/site-packages/airflow/cli/commands/task_command.py", line 483, in task_run
    task_return_code = _run_task_by_selected_method(args, _dag, ti)
                       ^^^^^^^^^^^^^^^^^^^^^^^^^^^^^^^^^^^^^^^^^^^^
  File "/usr/local/lib/python3.12/site-packages/airflow/cli/commands/task_command.py", line 256, in _run_task_by_selected_method
    return _run_raw_task(args, ti)
           ^^^^^^^^^^^^^^^^^^^^^^^
  File "/usr/local/lib/python3.12/site-packages/airflow/cli/commands/task_command.py", line 341, in _run_raw_task
    return ti._run_raw_task(
           ^^^^^^^^^^^^^^^^^
  File "/usr/local/lib/python3.12/site-packages/airflow/utils/session.py", line 97, in wrapper
    return func(*args, session=session, **kwargs)
           ^^^^^^^^^^^^^^^^^^^^^^^^^^^^^^^^^^^^^^
  File "/usr/local/lib/python3.12/site-packages/airflow/models/taskinstance.py", line 3005, in _run_raw_task
    return _run_raw_task(
           ^^^^^^^^^^^^^^
  File "/usr/local/lib/python3.12/site-packages/airflow/models/taskinstance.py", line 273, in _run_raw_task
    TaskInstance._execute_task_with_callbacks(
  File "/usr/local/lib/python3.12/site-packages/airflow/models/taskinstance.py", line 3159, in _execute_task_with_callbacks
    result = self._execute_task(context, task_orig)
             ^^^^^^^^^^^^^^^^^^^^^^^^^^^^^^^^^^^^^^
  File "/usr/local/lib/python3.12/site-packages/airflow/models/taskinstance.py", line 3183, in _execute_task
    return _execute_task(self, context, task_orig)
           ^^^^^^^^^^^^^^^^^^^^^^^^^^^^^^^^^^^^^^^
  File "/usr/local/lib/python3.12/site-packages/airflow/models/taskinstance.py", line 767, in _execute_task
    result = _execute_callable(context=context, **execute_callable_kwargs)
             ^^^^^^^^^^^^^^^^^^^^^^^^^^^^^^^^^^^^^^^^^^^^^^^^^^^^^^^^^^^^^
  File "/usr/local/lib/python3.12/site-packages/airflow/models/taskinstance.py", line 733, in _execute_callable
    return ExecutionCallableRunner(
           ^^^^^^^^^^^^^^^^^^^^^^^^
  File "/usr/local/lib/python3.12/site-packages/airflow/utils/operator_helpers.py", line 252, in run
    return self.func(*args, **kwargs)
           ^^^^^^^^^^^^^^^^^^^^^^^^^^
  File "/usr/local/lib/python3.12/site-packages/airflow/models/baseoperator.py", line 417, in wrapper
    return func(self, *args, **kwargs)
           ^^^^^^^^^^^^^^^^^^^^^^^^^^^
  File "/usr/local/lib/python3.12/site-packages/airflow/operators/python.py", line 238, in execute
    return_value = self.execute_callable()
                   ^^^^^^^^^^^^^^^^^^^^^^^
  File "/usr/local/lib/python3.12/site-packages/airflow/operators/python.py", line 256, in execute_callable
    return runner.run(*self.op_args, **self.op_kwargs)
           ^^^^^^^^^^^^^^^^^^^^^^^^^^^^^^^^^^^^^^^^^^^
  File "/usr/local/lib/python3.12/site-packages/airflow/utils/operator_helpers.py", line 252, in run
    return self.func(*args, **kwargs)
           ^^^^^^^^^^^^^^^^^^^^^^^^^^
  File "/opt/Tasks/transform_and_load_data/transform_and_load.py", line 40, in hosocongty_transform_and_load
    dwh_cursor.executemany(sql_insert, transformed_data)
psycopg2.errors.ForeignKeyViolation: insert or update on table "dim_company" violates foreign key constraint "dim_company_san_niem_yet_fkey"
DETAIL:  Key (san_niem_yet)=(Upcom) is not present in table "dim_exchange".

[2024-12-13T17:18:34.524+0000] {local_task_job_runner.py:266} INFO - Task exited with return code 1
[2024-12-13T17:18:34.573+0000] {taskinstance.py:3895} INFO - 0 downstream tasks scheduled from follow-on schedule check
[2024-12-13T17:18:34.584+0000] {local_task_job_runner.py:245} INFO - ::endgroup::
